Workbook

Sheet Code Pro
A1: PROV_CODE | B1: PROV_NAM_T
A2: 20 | B2: จ.ชลบุรี
A3: 21 | B3: จ.ระยอง
A4: 22 | B4: จ.จันทบุรี
A5: 23 | B5: จ.ตราด
A6: 24 | B6: จ.ฉะเชิงเทรา
A7: 25 | B7: จ.ปราจีนบุรี
A8: 26 | B8: จ.นครนายก
A9: 27 | B9: จ.สระแก้ว

Sheet RAW DATA
A1: FID | B1: Shape * | C1: FID_Amphoe | D1: AMP_CODE | E1: AMP_NAM_T | F1: AMP_NAM_E | G1: PROV_CODE | H1: REG_CODE | I1: AMP_ID | J1: FID_GridRa | K1: Id | L1: Input_FID | M1: lat | N1: lon | O1: 00_00Z_202 | P1: 00_00Z_203 | Q1: 00_00Z_204 | R1: 00_00Z_205 | S1: 00_00Z_206 | T1: 00_00Z_207 | U1: 00_00Z_208 | V1: 00_00Z_209 | W1: 00_00Z_210 | X1: Length | Y1: Area
A2: 0 | B2: Polygon | C2: 1 | D2: 1 | E2: อ.เมืองชลบุรี | F2: Amphoe Muang Chonburi | G2: 20 | H2: 2 | I2: 20010000 | J2: 678 | K2: 0 | L2: 13619 | M2: 13.284592 | N2: 100.93988 | O2: 1.52 | P2: 1.01 | Q2: 0.55 | R2: 0.2 | S2: 2.3 | T2: 32.52 | U2: 4.99 | V2: 1.3 | W2: 0 | X2: 32984.059 | Y2: 61459357
A3: 1 | B3: Polygon | C3: 1 | D3: 1 | E3: อ.เมืองชลบุรี | F3: Amphoe Muang Chonburi | G3: 20 | H3: 2 | I3: 20010000 | J3: 679 | K3: 0 | L3: 13618 | M3: 13.284592 | N3: 100.85674 | O3: 1.5 | P3: 0.07 | Q3: 0.54 | R3: 1.15 | S3: 2.24 | T3: 54.619999 | U3: 18.08 | V3: 1.32 | W3: 0.03 | X3: 532.43569 | Y3: 12606.372
A4: 2 | B4: Polygon | C4: 1 | D4: 1 | E4: อ.เมืองชลบุรี | F4: Amphoe Muang Chonburi | G4: 20 | H4: 2 | I4: 20010000 | J4: 680 | K4: 0 | L4: 13499 | M4: 13.203667 | N4: 100.93988 | O4: 0.74 | P4: 0.36 | Q4: 5.45 | R4: 0.65 | S4: 0.21 | T4: 52.720001 | U4: 6.51 | V4: 1.78 | W4: 2.4 | X4: 8386.2692 | Y4: 1662760.7
A5: 3 | B5: Polygon | C5: 1 | D5: 1 | E5: อ.เมืองชลบุรี | F5: Amphoe Muang Chonburi | G5: 20 | H5: 2 | I5: 20010000 | J5: 681 | K5: 0 | L5: 13739 | M5: 13.365479 | N5: 100.93988 | O5: 0 | P5: 3.54 | Q5: 2.05 | R5: 2.38 | S5: 1.35 | T5: 36.060001 | U5: 4.55 | V5: 0.22 | W5: 0 | X5: 27386.196 | Y5: 16159820
A6: 4 | B6: Polygon | C6: 1 | D6: 1 | E6: อ.เมืองชลบุรี | F6: Amphoe Muang Chonburi | G6: 20 | H6: 2 | I6: 20010000 | J6: 683 | K6: 0 | L6: 13741 | M6: 13.365479 | N6: 101.10615 | O6: 0.38 | P6: 15.7 | Q6: 7.94 | R6: 2.33 | S6: 0.05 | T6: 52.740002 | U6: 1.25 | V6: 0 | W6: 0 | X6: 4196.1118 | Y6: 339241.32
A7: 5 | B7: Polygon | C7: 1 | D7: 1 | E7: อ.เมืองชลบุรี | F7: Amphoe Muang Chonburi | G7: 20 | H7: 2 | I7: 20010000 | J7: 684 | K7: 0 | L7: 13859 | M7: 13.446358 | N7: 100.93988 | O7: 0.5 | P7: 5.71 | Q7: 0.03 | R7: 5 | S7: 5.15 | T7: 23.23 | U7: 6.55 | V7: 0.49 | W7: 0 | X7: 15834.741 | Y7: 7638855.7
A8: 6 | B8: Polygon | C8: 1 | D8: 1 | E8: อ.เมืองชลบุรี | F8: Amphoe Muang Chonburi | G8: 20 | H8: 2 | I8: 20010000 | J8: 692 | K8: 0 | L8: 13860 | M8: 13.446358 | N8: 101.02302 | O8: 0.03 | P8: 41.380001 | Q8: 4.11 | R8: 3.2 | S8: 0.97 | T8: 44.740002 | U8: 5.44 | V8: 0 | W8: 0 | X8: 31336.021 | Y8: 39719259
A9: 7 | B9: Polygon | C9: 1 | D9: 1 | E9: อ.เมืองชลบุรี | F9: Amphoe Muang Chonburi | G9: 20 | H9: 2 | I9: 20010000 | J9: 693 | K9: 0 | L9: 13740 | M9: 13.365479 | N9: 101.02302 | O9: 1.94 | P9: 16.65 | Q9: 16.65 | R9: 6.78 | S9: 0.44 | T9: 34.099998 | U9: 3.39 | V9: 0.05 | W9: 0 | X9: 41937.609 | Y9: 72989892
A10: 8 | B10: Polygon | C10: 1 | D10: 1 | E10: อ.เมืองชลบุรี | F10: Amphoe Muang Chonburi | G10: 20 | H10: 2 | I10: 20010000 | J10: 694 | K10: 0 | L10: 13621 | M10: 13.284592 | N10: 101.10615 | O10: 0.01 | P10: 27.23 | Q10: 2.86 | R10: 1.07 | S10: 0 | T10: 25.360001 | U10: 1.22 | V10: 0.03 | W10: 0 | X10: 10020.996 | Y10: 3033125.3
A11: 9 | B11: Polygon | C11: 1 | D11: 1 | E11: อ.เมืองชลบุรี | F11: Amphoe Muang Chonburi | G11: 20 | H11: 2 | I11: 20010000 | J11: 695 | K11: 0 | L11: 13620 | M11: 13.284592 | N11: 101.02302 | O11: 2.91 | P11: 8.71 | Q11: 1.09 | R11: 0.09 | S11: 0.45 | T11: 35.630001 | U11: 1.78 | V11: 0.02 | W11: 0 | X11: 31810.657 | Y11: 51942792
A12: 10 | B12: Polygon | C12: 1 | D12: 1 | E12: อ.เมืองชลบุรี | F12: Amphoe Muang Chonburi | G12: 20 | H12: 2 | I12: 20010000 | J12: 719 | K12: 0 | L12: 13861 | M12: 13.446358 | N12: 101.10615 | O12: 2.3 | P12: 43.209999 | Q12: 21.57 | R12: 5.38 | S12: 0.03 | T12: 60.759998 | U12: 1.86 | V12: 0 | W12: 0 | X12: 3706.4838 | Y12: 715966.14
A13: 11 | B13: Polygon | C13: 2 | D13: 2 | E13: อ.บ้านบึง | F13: Amphoe Ban Bung | G13: 20 | H13: 2 | I13: 20020000 | J13: 683 | K13: 0 | L13: 13741 | M13: 13.365479 | N13: 101.10615 | O13: 0.38 | P13: 15.7 | Q13: 7.94 | R13: 2.33 | S13: 0.05 | T13: 52.740002 | U13: 1.25 | V13: 0 | W13: 0 | X13: 40208.175 | Y13: 50752081
... A1063: 1061 | B1063: Polygon | C1063: 68 | D1063: 9 | E1063: อ.วังสมบูรณ์ | F1063: King Amphoe Wang Sombun | G1063: 27 | H1063: 2 | I1063: 27090000 | J1063: 1000 | K1063: 0 | L1063: 13635 | M1063: 13.284592 | N1063: 102.27006 | O1063: 3.38 | P1063: 44.349998 | Q1063: 0.14 | R1063: 0.39 | S1063: 9.15 | T1063: 38.68 | U1063: 15.62 | V1063: 0.83 | W1063: 0.31 | X1063: 32145.295 | Y1063: 46383189
A1064: 1062 | B1064: Polygon | C1064: 0 | D1064: - | E1064: เขตปกครองพิเศษกร | F1064: Bangkok | G1064: - | H1064: 1 | I1064: - | J1064: 724 | K1064: 0 | L1064: 14339 | M1064: 13.769569 | N1064: 100.93988 | O1064: 7.61 | P1064: 0.26 | Q1064: 37.810001 | R1064: 0 | S1064: 0.74 | T1064: 52.41 | U1064: 2.73 | V1064: 0 | W1064: 0 | X1064: 2.766567 | Y1064: 0.00355
A1065: 1063 | B1065: Polygon | C1065: 38 | D1065: 1 | E1065: อ.เมืองฉะเชิงเทรา | F1065: Amphoe Muang Chachoengsao | G1065: 24 | H1065: 2 | I1065: 24010000 | J1065: 724 | K1065: 0 | L1065: 14339 | M1065: 13.769569 | N1065: 100.93988 | O1065: 7.61 | P1065: 0.26 | Q1065: 37.810001 | R1065: 0 | S1065: 0.74 | T1065: 52.41 | U1065: 2.73 | V1065: 0 | W1065: 0 | X1065: 2.766567 | Y1065: 0.00355
A1066: 1064 | B1066: Polygon | C1066: 0 | D1066: - | E1066: เขตปกครองพิเศษกร | F1066: Bangkok | G1066: - | H1066: 1 | I1066: - | J1066: 724 | K1066: 0 | L1066: 14339 | M1066: 13.769569 | N1066: 100.93988 | O1066: 7.61 | P1066: 0.26 | Q1066: 37.810001 | R1066: 0 | S1066: 0.74 | T1066: 52.41 | U1066: 2.73 | V1066: 0 | W1066: 0 | X1066: 600.97047 | Y1066: 0.772639
A1067: 1065 | B1067: Polygon | C1067: 40 | D1067: 3 | E1067: อ.บางน้ำเปรี้ยว | F1067: Amphoe Bang Nam Pieo | G1067: 24 | H1067: 2 | I1067: 24030000 | J1067: 724 | K1067: 0 | L1067: 14339 | M1067: 13.769569 | N1067: 100.93988 | O1067: 7.61 | P1067: 0.26 | Q1067: 37.810001 | R1067: 0 | S1067: 0.74 | T1067: 52.41 | U1067: 2.73 | V1067: 0 | W1067: 0 | X1067: 600.97047 | Y1067: 0.772639
A1068: 1066 | B1068: Polygon | C1068: 0 | D1068: - | E1068: เขตปกครองพิเศษกร | F1068: Bangkok | G1068: - | H1068: 1 | I1068: - | J1068: 726 | K1068: 0 | L1068: 14459 | M1068: 13.850304 | N1068: 100.93988 | O1068: 1.86 | P1068: 0 | Q1068: 62.779999 | R1068: 0.24 | S1068: 0.85 | T1068: 22.469999 | U1068: 6.77 | V1068: 0 | W1068: 0 | X1068: 43.520061 | Y1068: 0.25223
A1069: 1067 | B1069: Polygon | C1069: 40 | D1069: 3 | E1069: อ.บางน้ำเปรี้ยว | F1069: Amphoe Bang Nam Pieo | G1069: 24 | H1069: 2 | I1069: 24030000 | J1069: 726 | K1069: 0 | L1069: 14459 | M1069: 13.850304 | N1069: 100.93988 | O1069: 1.86 | P1069: 0 | Q1069: 62.779999 | R1069: 0.24 | S1069: 0.85 | T1069: 22.469999 | U1069: 6.77 | V1069: 0 | W1069: 0 | X1069: 43.520061 | Y1069: 0.25223

Sheet Data
A1: FID | B1: Shape * | C1: FID_Amphoe | D1: AMP_CODE | E1: AMP_NAM_T | F1: AMP_NAM_E | G1: PROV_CODE | H1: REG_CODE | I1: AMP_ID | J1: FID_GridRa | K1: Id | L1: Input_FID | M1: lat | N1: lon | O1: 00_00Z_202 | P1: 00_00Z_203 | Q1: 00_00Z_204 | R1: 00_00Z_205 | S1: 00_00Z_206 | T1: 00_00Z_207 | U1: 00_00Z_208 | V1: 00_00Z_209 | W1: 00_00Z_210 | X1: Length | Y1: Area | Z1: จัวหวัด | AA1: 00_00Z_202 | AB1: 00_00Z_203 | AC1: 00_00Z_204 | AD1: 00_00Z_205 | AE1: 00_00Z_206 | AF1: 00_00Z_207 | AG1: 00_00Z_208 | AH1: 00_00Z_209 | AI1: 00_00Z_210
A2: 0 | B2: Polygon | C2: 1 | D2: 1 | E2: อ.เมืองชลบุรี | F2: Amphoe Muang Chonburi | G2: 20 | H2: 2 | I2: 20010000 | J2: 678 | K2: 0 | L2: 13619 | M2: 13.284592 | N2: 100.93988 | O2: 1.52 | P2: 1.01 | Q2: 0.55 | R2: 0.2 | S2: 2.3 | T2: 32.52 | U2: 4.99 | V2: 1.3 | W2: 0 | X2: 32984.059 | Y2: 61459357 | Z2: =VLOOKUP(G2,'Code Pro'!$A$2:$B$9,2,FALSE) -> จ.ชลบุรี | AA2: =+O2*$Y2 -> 93418223 | AB2: =+P2*$Y2 -> 62073951 | AC2: =+Q2*$Y2 -> 33802647 | AD2: =+R2*$Y2 -> 12291871 | AE2: =+S2*$Y2 -> 1.4135652e+08 | AF2: =+T2*$Y2 -> 1.9986583e+09 | AG2: =+U2*$Y2 -> 3.0668219e+08 | AH2: =+V2*$Y2 -> 79897165 | AI2: =+W2*$Y2 -> 0
A3: 1 | B3: Polygon | C3: 1 | D3: 1 | E3: อ.เมืองชลบุรี | F3: Amphoe Muang Chonburi | G3: 20 | H3: 2 | I3: 20010000 | J3: 679 | K3: 0 | L3: 13618 | M3: 13.284592 | N3: 100.85674 | O3: 1.5 | P3: 0.07 | Q3: 0.54 | R3: 1.15 | S3: 2.24 | T3: 54.619999 | U3: 18.08 | V3: 1.32 | W3: 0.03 | X3: 532.43569 | Y3: 12606.372 | Z3: =VLOOKUP(G3,'Code Pro'!$A$2:$B$9,2,FALSE) -> จ.ชลบุรี | AA3: =+O3*$Y3 -> 18909.559 | AB3: =+P3*$Y3 -> 882.44607 | AC3: =+Q3*$Y3 -> 6807.4411 | AD3: =+R3*$Y3 -> 14497.328 | AE3: =+S3*$Y3 -> 28238.274 | AF3: =+T3*$Y3 -> 688560.05 | AG3: =+U3*$Y3 -> 227923.21 | AH3: =+V3*$Y3 -> 16640.412 | AI3: =+W3*$Y3 -> 378.19117
A4: 2 | B4: Polygon | C4: 1 | D4: 1 | E4: อ.เมืองชลบุรี | F4: Amphoe Muang Chonburi | G4: 20 | H4: 2 | I4: 20010000 | J4: 680 | K4: 0 | L4: 13499 | M4: 13.203667 | N4: 100.93988 | O4: 0.74 | P4: 0.36 | Q4: 5.45 | R4: 0.65 | S4: 0.21 | T4: 52.720001 | U4: 6.51 | V4: 1.78 | W4: 2.4 | X4: 8386.2692 | Y4: 1662760.7 | Z4: =VLOOKUP(G4,'Code Pro'!$A$2:$B$9,2,FALSE) -> จ.ชลบุรี | AA4: =+O4*$Y4 -> 1230442.9 | AB4: =+P4*$Y4 -> 598593.86 | AC4: =+Q4*$Y4 -> 9062045.9 | AD4: =+R4*$Y4 -> 1080794.5 | AE4: =+S4*$Y4 -> 349179.75 | AF4: =+T4*$Y4 -> 87660747 | AG4: =+U4*$Y4 -> 10824572 | AH4: =+V4*$Y4 -> 2959714.1 | AI4: =+W4*$Y4 -> 3990625.7
A5: 3 | B5: Polygon | C5: 1 | D5: 1 | E5: อ.เมืองชลบุรี | F5: Amphoe Muang Chonburi | G5: 20 | H5: 2 | I5: 20010000 | J5: 681 | K5: 0 | L5: 13739 | M5: 13.365479 | N5: 100.93988 | O5: 0 | P5: 3.54 | Q5: 2.05 | R5: 2.38 | S5: 1.35 | T5: 36.060001 | U5: 4.55 | V5: 0.22 | W5: 0 | X5: 27386.196 | Y5: 16159820 | Z5: =VLOOKUP(G5,'Code Pro'!$A$2:$B$9,2,FALSE) -> จ.ชลบุรี | AA5: =+O5*$Y5 -> 0 | AB5: =+P5*$Y5 -> 57205763 | AC5: =+Q5*$Y5 -> 33127631 | AD5: =+R5*$Y5 -> 38460372 | AE5: =+S5*$Y5 -> 21815757 | AF5: =+T5*$Y5 -> 5.8272313e+08 | AG5: =+U5*$Y5 -> 73527182 | AH5: =+V5*$Y5 -> 3555160.4 | AI5: =+W5*$Y5 -> 0
A6: 4 | B6: Polygon | C6: 1 | D6: 1 | E6: อ.เมืองชลบุรี | F6: Amphoe Muang Chonburi | G6: 20 | H6: 2 | I6: 20010000 | J6: 683 | K6: 0 | L6: 13741 | M6: 13.365479 | N6: 101.10615 | O6: 0.38 | P6: 15.7 | Q6: 7.94 | R6: 2.33 | S6: 0.05 | T6: 52.740002 | U6: 1.25 | V6: 0 | W6: 0 | X6: 4196.1118 | Y6: 339241.32 | Z6: =VLOOKUP(G6,'Code Pro'!$A$2:$B$9,2,FALSE) -> จ.ชลบุรี | AA6: =+O6*$Y6 -> 128911.7 | AB6: =+P6*$Y6 -> 5326088.7 | AC6: =+Q6*$Y6 -> 2693576.1 | AD6: =+R6*$Y6 -> 790432.27 | AE6: =+S6*$Y6 -> 16962.066 | AF6: =+T6*$Y6 -> 17891588 | AG6: =+U6*$Y6 -> 424051.65 | AH6: =+V6*$Y6 -> 0 | AI6: =+W6*$Y6 -> 0
A7: 5 | B7: Polygon | C7: 1 | D7: 1 | E7: อ.เมืองชลบุรี | F7: Amphoe Muang Chonburi | G7: 20 | H7: 2 | I7: 20010000 | J7: 684 | K7: 0 | L7: 13859 | M7: 13.446358 | N7: 100.93988 | O7: 0.5 | P7: 5.71 | Q7: 0.03 | R7: 5 | S7: 5.15 | T7: 23.23 | U7: 6.55 | V7: 0.49 | W7: 0 | X7: 15834.741 | Y7: 7638855.7 | Z7: =VLOOKUP(G7,'Code Pro'!$A$2:$B$9,2,FALSE) -> จ.ชลบุรี | AA7: =+O7*$Y7 -> 3819427.9 | AB7: =+P7*$Y7 -> 43617866 | AC7: =+Q7*$Y7 -> 229165.67 | AD7: =+R7*$Y7 -> 38194279 | AE7: =+S7*$Y7 -> 39340107 | AF7: =+T7*$Y7 -> 1.7745062e+08 | AG7: =+U7*$Y7 -> 50034505 | AH7: =+V7*$Y7 -> 3743039.3 | AI7: =+W7*$Y7 -> 0
A8: 6 | B8: Polygon | C8: 1 | D8: 1 | E8: อ.เมืองชลบุรี | F8: Amphoe Muang Chonburi | G8: 20 | H8: 2 | I8: 20010000 | J8: 692 | K8: 0 | L8: 13860 | M8: 13.446358 | N8: 101.02302 | O8: 0.03 | P8: 41.380001 | Q8: 4.11 | R8: 3.2 | S8: 0.97 | T8: 44.740002 | U8: 5.44 | V8: 0 | W8: 0 | X8: 31336.021 | Y8: 39719259 | Z8: =VLOOKUP(G8,'Code Pro'!$A$2:$B$9,2,FALSE) -> จ.ชลบุรี | AA8: =+O8*$Y8 -> 1191577.8 | AB8: =+P8*$Y8 -> 1.643583e+09 | AC8: =+Q8*$Y8 -> 1.6324615e+08 | AD8: =+R8*$Y8 -> 1.2710163e+08 | AE8: =+S8*$Y8 -> 38527681 | AF8: =+T8*$Y8 -> 1.7770397e+09 | AG8: =+U8*$Y8 -> 2.1607277e+08 | AH8: =+V8*$Y8 -> 0 | AI8: =+W8*$Y8 -> 0
A9: 7 | B9: Polygon | C9: 1 | D9: 1 | E9: อ.เมืองชลบุรี | F9: Amphoe Muang Chonburi | G9: 20 | H9: 2 | I9: 20010000 | J9: 693 | K9: 0 | L9: 13740 | M9: 13.365479 | N9: 101.02302 | O9: 1.94 | P9: 16.65 | Q9: 16.65 | R9: 6.78 | S9: 0.44 | T9: 34.099998 | U9: 3.39 | V9: 0.05 | W9: 0 | X9: 41937.609 | Y9: 72989892 | Z9: =VLOOKUP(G9,'Code Pro'!$A$2:$B$9,2,FALSE) -> จ.ชลบุรี | AA9: =+O9*$Y9 -> 1.4160039e+08 | AB9: =+P9*$Y9 -> 1.2152817e+09 | AC9: =+Q9*$Y9 -> 1.2152817e+09 | AD9: =+R9*$Y9 -> 4.9487147e+08 | AE9: =+S9*$Y9 -> 32115553 | AF9: =+T9*$Y9 -> 2.4889552e+09 | AG9: =+U9*$Y9 -> 2.4743573e+08 | AH9: =+V9*$Y9 -> 3649494.6 | AI9: =+W9*$Y9 -> 0
A10: 8 | B10: Polygon | C10: 1 | D10: 1 | E10: อ.เมืองชลบุรี | F10: Amphoe Muang Chonburi | G10: 20 | H10: 2 | I10: 20010000 | J10: 694 | K10: 0 | L10: 13621 | M10: 13.284592 | N10: 101.10615 | O10: 0.01 | P10: 27.23 | Q10: 2.86 | R10: 1.07 | S10: 0 | T10: 25.360001 | U10: 1.22 | V10: 0.03 | W10: 0 | X10: 10020.996 | Y10: 3033125.3 | Z10: =VLOOKUP(G10,'Code Pro'!$A$2:$B$9,2,FALSE) -> จ.ชลบุรี | AA10: =+O10*$Y10 -> 30331.253 | AB10: =+P10*$Y10 -> 82592003 | AC10: =+Q10*$Y10 -> 8674738.4 | AD10: =+R10*$Y10 -> 3245444.1 | AE10: =+S10*$Y10 -> 0 | AF10: =+T10*$Y10 -> 76920061 | AG10: =+U10*$Y10 -> 3700412.9 | AH10: =+V10*$Y10 -> 90993.76 | AI10: =+W10*$Y10 -> 0
A11: 9 | B11: Polygon | C11: 1 | D11: 1 | E11: อ.เมืองชลบุรี | F11: Amphoe Muang Chonburi | G11: 20 | H11: 2 | I11: 20010000 | J11: 695 | K11: 0 | L11: 13620 | M11: 13.284592 | N11: 101.02302 | O11: 2.91 | P11: 8.71 | Q11: 1.09 | R11: 0.09 | S11: 0.45 | T11: 35.630001 | U11: 1.78 | V11: 0.02 | W11: 0 | X11: 31810.657 | Y11: 51942792 | Z11: =VLOOKUP(G11,'Code Pro'!$A$2:$B$9,2,FALSE) -> จ.ชลบุรี | AA11: =+O11*$Y11 -> 1.5115352e+08 | AB11: =+P11*$Y11 -> 4.5242172e+08 | AC11: =+Q11*$Y11 -> 56617643 | AD11: =+R11*$Y11 -> 4674851.3 | AE11: =+S11*$Y11 -> 23374256 | AF11: =+T11*$Y11 -> 1.8507217e+09 | AG11: =+U11*$Y11 -> 92458169 | AH11: =+V11*$Y11 -> 1038855.8 | AI11: =+W11*$Y11 -> 0
A12: 10 | B12: Polygon | C12: 1 | D12: 1 | E12: อ.เมืองชลบุรี | F12: Amphoe Muang Chonburi | G12: 20 | H12: 2 | I12: 20010000 | J12: 719 | K12: 0 | L12: 13861 | M12: 13.446358 | N12: 101.10615 | O12: 2.3 | P12: 43.209999 | Q12: 21.57 | R12: 5.38 | S12: 0.03 | T12: 60.759998 | U12: 1.86 | V12: 0 | W12: 0 | X12: 3706.4838 | Y12: 715966.14 | Z12: =VLOOKUP(G12,'Code Pro'!$A$2:$B$9,2,FALSE) -> จ.ชลบุรี | AA12: =+O12*$Y12 -> 1646722.1 | AB12: =+P12*$Y12 -> 30936896 | AC12: =+Q12*$Y12 -> 15443390 | AD12: =+R12*$Y12 -> 3851897.9 | AE12: =+S12*$Y12 -> 21478.984 | AF12: =+T12*$Y12 -> 43502102 | AG12: =+U12*$Y12 -> 1331697 | AH12: =+V12*$Y12 -> 0 | AI12: =+W12*$Y12 -> 0
A13: 11 | B13: Polygon | C13: 2 | D13: 2 | E13: อ.บ้านบึง | F13: Amphoe Ban Bung | G13: 20 | H13: 2 | I13: 20020000 | J13: 683 | K13: 0 | L13: 13741 | M13: 13.365479 | N13: 101.10615 | O13: 0.38 | P13: 15.7 | Q13: 7.94 | R13: 2.33 | S13: 0.05 | T13: 52.740002 | U13: 1.25 | V13: 0 | W13: 0 | X13: 40208.175 | Y13: 50752081 | Z13: =VLOOKUP(G13,'Code Pro'!$A$2:$B$9,2,FALSE) -> จ.ชลบุรี | AA13: =+O13*$Y13 -> 19285791 | AB13: =+P13*$Y13 -> 7.9680768e+08 | AC13: =+Q13*$Y13 -> 4.0297153e+08 | AD13: =+R13*$Y13 -> 1.1825235e+08 | AE13: =+S13*$Y13 -> 2537604.1 | AF13: =+T13*$Y13 -> 2.6766649e+09 | AG13: =+U13*$Y13 -> 63440102 | AH13: =+V13*$Y13 -> 0 | AI13: =+W13*$Y13 -> 0
... A1063: 1061 | B1063: Polygon | C1063: 68 | D1063: 9 | E1063: อ.วังสมบูรณ์ | F1063: King Amphoe Wang Sombun | G1063: 27 | H1063: 2 | I1063: 27090000 | J1063: 1000 | K1063: 0 | L1063: 13635 | M1063: 13.284592 | N1063: 102.27006 | O1063: 3.38 | P1063: 44.349998 | Q1063: 0.14 | R1063: 0.39 | S1063: 9.15 | T1063: 38.68 | U1063: 15.62 | V1063: 0.83 | W1063: 0.31 | X1063: 32145.295 | Y1063: 46383189 | Z1063: =VLOOKUP(G1063,'Code Pro'!$A$2:$B$9,2,FALSE) -> จ.สระแก้ว | AA1063: =+O1063*$Y1063 -> 1.5677518e+08 | AB1063: =+P1063*$Y1063 -> 2.0570943e+09 | AC1063: =+Q1063*$Y1063 -> 6493646.4 | AD1063: =+R1063*$Y1063 -> 18089444 | AE1063: =+S1063*$Y1063 -> 4.2440618e+08 | AF1063: =+T1063*$Y1063 -> 1.7941017e+09 | AG1063: =+U1063*$Y1063 -> 7.2450541e+08 | AH1063: =+V1063*$Y1063 -> 38498047 | AI1063: =+W1063*$Y1063 -> 14378789
A1064: 1062 | B1064: Polygon | C1064: 0 | D1064: - | E1064: เขตปกครองพิเศษกร | F1064: Bangkok | G1064: - | H1064: 1 | I1064: - | J1064: 724 | K1064: 0 | L1064: 14339 | M1064: 13.769569 | N1064: 100.93988 | O1064: 7.61 | P1064: 0.26 | Q1064: 37.810001 | R1064: 0 | S1064: 0.74 | T1064: 52.41 | U1064: 2.73 | V1064: 0 | W1064: 0 | X1064: 2.766567 | Y1064: 0.00355 | Z1064: =VLOOKUP(G1064,'Code Pro'!$A$2:$B$9,2,FALSE) -> #N/A | AA1064: =+O1064*$Y1064 -> 0.0270155 | AB1064: =+P1064*$Y1064 -> 0.000923 | AC1064: =+Q1064*$Y1064 -> 0.1342255 | AD1064: =+R1064*$Y1064 -> 0 | AE1064: =+S1064*$Y1064 -> 0.002627 | AF1064: =+T1064*$Y1064 -> 0.1860555 | AG1064: =+U1064*$Y1064 -> 0.0096915 | AH1064: =+V1064*$Y1064 -> 0 | AI1064: =+W1064*$Y1064 -> 0
A1065: 1063 | B1065: Polygon | C1065: 38 | D1065: 1 | E1065: อ.เมืองฉะเชิงเทรา | F1065: Amphoe Muang Chachoengsao | G1065: 24 | H1065: 2 | I1065: 24010000 | J1065: 724 | K1065: 0 | L1065: 14339 | M1065: 13.769569 | N1065: 100.93988 | O1065: 7.61 | P1065: 0.26 | Q1065: 37.810001 | R1065: 0 | S1065: 0.74 | T1065: 52.41 | U1065: 2.73 | V1065: 0 | W1065: 0 | X1065: 2.766567 | Y1065: 0.00355 | Z1065: =VLOOKUP(G1065,'Code Pro'!$A$2:$B$9,2,FALSE) -> จ.ฉะเชิงเทรา | AA1065: =+O1065*$Y1065 -> 0.0270155 | AB1065: =+P1065*$Y1065 -> 0.000923 | AC1065: =+Q1065*$Y1065 -> 0.1342255 | AD1065: =+R1065*$Y1065 -> 0 | AE1065: =+S1065*$Y1065 -> 0.002627 | AF1065: =+T1065*$Y1065 -> 0.1860555 | AG1065: =+U1065*$Y1065 -> 0.0096915 | AH1065: =+V1065*$Y1065 -> 0 | AI1065: =+W1065*$Y1065 -> 0
A1066: 1064 | B1066: Polygon | C1066: 0 | D1066: - | E1066: เขตปกครองพิเศษกร | F1066: Bangkok | G1066: - | H1066: 1 | I1066: - | J1066: 724 | K1066: 0 | L1066: 14339 | M1066: 13.769569 | N1066: 100.93988 | O1066: 7.61 | P1066: 0.26 | Q1066: 37.810001 | R1066: 0 | S1066: 0.74 | T1066: 52.41 | U1066: 2.73 | V1066: 0 | W1066: 0 | X1066: 600.97047 | Y1066: 0.772639 | Z1066: =VLOOKUP(G1066,'Code Pro'!$A$2:$B$9,2,FALSE) -> #N/A | AA1066: =+O1066*$Y1066 -> 5.8797828 | AB1066: =+P1066*$Y1066 -> 0.20088614 | AC1066: =+Q1066*$Y1066 -> 29.213481 | AD1066: =+R1066*$Y1066 -> 0 | AE1066: =+S1066*$Y1066 -> 0.57175286 | AF1066: =+T1066*$Y1066 -> 40.49401 | AG1066: =+U1066*$Y1066 -> 2.1093045 | AH1066: =+V1066*$Y1066 -> 0 | AI1066: =+W1066*$Y1066 -> 0
A1067: 1065 | B1067: Polygon | C1067: 40 | D1067: 3 | E1067: อ.บางน้ำเปรี้ยว | F1067: Amphoe Bang Nam Pieo | G1067: 24 | H1067: 2 | I1067: 24030000 | J1067: 724 | K1067: 0 | L1067: 14339 | M1067: 13.769569 | N1067: 100.93988 | O1067: 7.61 | P1067: 0.26 | Q1067: 37.810001 | R1067: 0 | S1067: 0.74 | T1067: 52.41 | U1067: 2.73 | V1067: 0 | W1067: 0 | X1067: 600.97047 | Y1067: 0.772639 | Z1067: =VLOOKUP(G1067,'Code Pro'!$A$2:$B$9,2,FALSE) -> จ.ฉะเชิงเทรา | AA1067: =+O1067*$Y1067 -> 5.8797828 | AB1067: =+P1067*$Y1067 -> 0.20088614 | AC1067: =+Q1067*$Y1067 -> 29.213481 | AD1067: =+R1067*$Y1067 -> 0 | AE1067: =+S1067*$Y1067 -> 0.57175286 | AF1067: =+T1067*$Y1067 -> 40.49401 | AG1067: =+U1067*$Y1067 -> 2.1093045 | AH1067: =+V1067*$Y1067 -> 0 | AI1067: =+W1067*$Y1067 -> 0
A1068: 1066 | B1068: Polygon | C1068: 0 | D1068: - | E1068: เขตปกครองพิเศษกร | F1068: Bangkok | G1068: - | H1068: 1 | I1068: - | J1068: 726 | K1068: 0 | L1068: 14459 | M1068: 13.850304 | N1068: 100.93988 | O1068: 1.86 | P1068: 0 | Q1068: 62.779999 | R1068: 0.24 | S1068: 0.85 | T1068: 22.469999 | U1068: 6.77 | V1068: 0 | W1068: 0 | X1068: 43.520061 | Y1068: 0.25223 | Z1068: =VLOOKUP(G1068,'Code Pro'!$A$2:$B$9,2,FALSE) -> #N/A | AA1068: =+O1068*$Y1068 -> 0.4691478 | AB1068: =+P1068*$Y1068 -> 0 | AC1068: =+Q1068*$Y1068 -> 15.834999 | AD1068: =+R1068*$Y1068 -> 0.0605352 | AE1068: =+S1068*$Y1068 -> 0.2143955 | AF1068: =+T1068*$Y1068 -> 5.6676078 | AG1068: =+U1068*$Y1068 -> 1.7075971 | AH1068: =+V1068*$Y1068 -> 0 | AI1068: =+W1068*$Y1068 -> 0
A1069: 1067 | B1069: Polygon | C1069: 40 | D1069: 3 | E1069: อ.บางน้ำเปรี้ยว | F1069: Amphoe Bang Nam Pieo | G1069: 24 | H1069: 2 | I1069: 24030000 | J1069: 726 | K1069: 0 | L1069: 14459 | M1069: 13.850304 | N1069: 100.93988 | O1069: 1.86 | P1069: 0 | Q1069: 62.779999 | R1069: 0.24 | S1069: 0.85 | T1069: 22.469999 | U1069: 6.77 | V1069: 0 | W1069: 0 | X1069: 43.520061 | Y1069: 0.25223 | Z1069: =VLOOKUP(G1069,'Code Pro'!$A$2:$B$9,2,FALSE) -> จ.ฉะเชิงเทรา | AA1069: =+O1069*$Y1069 -> 0.4691478 | AB1069: =+P1069*$Y1069 -> 0 | AC1069: =+Q1069*$Y1069 -> 15.834999 | AD1069: =+R1069*$Y1069 -> 0.0605352 | AE1069: =+S1069*$Y1069 -> 0.2143955 | AF1069: =+T1069*$Y1069 -> 5.6676078 | AG1069: =+U1069*$Y1069 -> 1.7075971 | AH1069: =+V1069*$Y1069 -> 0 | AI1069: =+W1069*$Y1069 -> 0

Sheet WeightCal
D1: ฝน x พื้นที่ | M1: ฝน
A2: จังหวัด | B2: อำเภอ | C2: พื้นที่ (ตร.ม.) | D2: 00_00Z_202 | E2: 00_00Z_203 | F2: 00_00Z_204 | G2: 00_00Z_205 | H2: 00_00Z_206 | I2: 00_00Z_207 | J2: 00_00Z_208 | K2: 00_00Z_209 | L2: 00_00Z_210 | M2: 00_00Z_202 | N2: 00_00Z_203 | O2: 00_00Z_204 | P2: 00_00Z_205 | Q2: 00_00Z_206 | R2: 00_00Z_207 | S2: 00_00Z_208 | T2: 00_00Z_209 | U2: 00_00Z_210
A3: จ.ฉะเชิงเทรา | B3: อ.คลองเขื่อน | C3: =SUMIFS(Data!$Y$2:$Y$2000,Data!$E$2:$E$2000,WeightCal!B3) -> 1.0716861e+08 | D3: =SUMIFS(Data!AA$2:AA$2000,Data!$E$2:$E$2000,WeightCal!$B3) -> 6.3986342e+09 | E3: =SUMIFS(Data!AB$2:AB$2000,Data!$E$2:$E$2000,WeightCal!$B3) -> 2.2528593e+08 | F3: =SUMIFS(Data!AC$2:AC$2000,Data!$E$2:$E$2000,WeightCal!$B3) -> 8.462009e+08 | G3: =SUMIFS(Data!AD$2:AD$2000,Data!$E$2:$E$2000,WeightCal!$B3) -> 15280717 | H3: =SUMIFS(Data!AE$2:AE$2000,Data!$E$2:$E$2000,WeightCal!$B3) -> 1.3927615e+08 | I3: =SUMIFS(Data!AF$2:AF$2000,Data!$E$2:$E$2000,WeightCal!$B3) -> 1.2979234e+09 | J3: =SUMIFS(Data!AG$2:AG$2000,Data!$E$2:$E$2000,WeightCal!$B3) -> 3.269125e+09 | K3: =SUMIFS(Data!AH$2:AH$2000,Data!$E$2:$E$2000,WeightCal!$B3) -> 443468.62 | L3: =SUMIFS(Data!AI$2:AI$2000,Data!$E$2:$E$2000,WeightCal!$B3) -> 0 | M3: =+D3/$C3 -> 59.706233 | N3: =+E3/$C3 -> 2.1021633 | O3: =+F3/$C3 -> 7.895977 | P3: =+G3/$C3 -> 0.14258575 | Q3: =+H3/$C3 -> 1.2995983 | R3: =+I3/$C3 -> 12.11104 | S3: =+J3/$C3 -> 30.5045 | T3: =+K3/$C3 -> 0.0041380457 | U3: =+L3/$C3 -> 0
B4: อ.ท่าตะเกียบ | C4: =SUMIFS(Data!$Y$2:$Y$2000,Data!$E$2:$E$2000,WeightCal!B4) -> 1.4226099e+09 | D4: =SUMIFS(Data!AA$2:AA$2000,Data!$E$2:$E$2000,WeightCal!$B4) -> 1.472795e+10 | E4: =SUMIFS(Data!AB$2:AB$2000,Data!$E$2:$E$2000,WeightCal!$B4) -> 5.6988864e+09 | F4: =SUMIFS(Data!AC$2:AC$2000,Data!$E$2:$E$2000,WeightCal!$B4) -> 3.1945944e+09 | G4: =SUMIFS(Data!AD$2:AD$2000,Data!$E$2:$E$2000,WeightCal!$B4) -> 7.6757604e+08 | H4: =SUMIFS(Data!AE$2:AE$2000,Data!$E$2:$E$2000,WeightCal!$B4) -> 9.9886923e+09 | I4: =SUMIFS(Data!AF$2:AF$2000,Data!$E$2:$E$2000,WeightCal!$B4) -> 1.4725965e+10 | J4: =SUMIFS(Data!AG$2:AG$2000,Data!$E$2:$E$2000,WeightCal!$B4) -> 3.3698244e+10 | K4: =SUMIFS(Data!AH$2:AH$2000,Data!$E$2:$E$2000,WeightCal!$B4) -> 9.5686739e+08 | L4: =SUMIFS(Data!AI$2:AI$2000,Data!$E$2:$E$2000,WeightCal!$B4) -> 19108296 | M4: =+D4/$C4 -> 10.352768 | N4: =+E4/$C4 -> 4.0059375 | O4: =+F4/$C4 -> 2.2455871 | P4: =+G4/$C4 -> 0.53955483 | Q4: =+H4/$C4 -> 7.0213853 | R4: =+I4/$C4 -> 10.351372 | S4: =+J4/$C4 -> 23.687621 | T4: =+K4/$C4 -> 0.67261403 | U4: =+L4/$C4 -> 0.013431859
B5: อ.บางคล้า | C5: =SUMIFS(Data!$Y$2:$Y$2000,Data!$E$2:$E$2000,WeightCal!B5) -> 2.3559875e+08 | D5: =SUMIFS(Data!AA$2:AA$2000,Data!$E$2:$E$2000,WeightCal!$B5) -> 1.0591188e+10 | E5: =SUMIFS(Data!AB$2:AB$2000,Data!$E$2:$E$2000,WeightCal!$B5) -> 3.8471259e+08 | F5: =SUMIFS(Data!AC$2:AC$2000,Data!$E$2:$E$2000,WeightCal!$B5) -> 1.9720441e+09 | G5: =SUMIFS(Data!AD$2:AD$2000,Data!$E$2:$E$2000,WeightCal!$B5) -> 16949885 | H5: =SUMIFS(Data!AE$2:AE$2000,Data!$E$2:$E$2000,WeightCal!$B5) -> 3.6200856e+08 | I5: =SUMIFS(Data!AF$2:AF$2000,Data!$E$2:$E$2000,WeightCal!$B5) -> 3.4828308e+09 | J5: =SUMIFS(Data!AG$2:AG$2000,Data!$E$2:$E$2000,WeightCal!$B5) -> 5.410628e+09 | K5: =SUMIFS(Data!AH$2:AH$2000,Data!$E$2:$E$2000,WeightCal!$B5) -> 49800401 | L5: =SUMIFS(Data!AI$2:AI$2000,Data!$E$2:$E$2000,WeightCal!$B5) -> 0 | M5: =+D5/$C5 -> 44.954346 | N5: =+E5/$C5 -> 1.6329144 | O5: =+F5/$C5 -> 8.3703503 | P5: =+G5/$C5 -> 0.071943866 | Q5: =+H5/$C5 -> 1.536547 | R5: =+I5/$C5 -> 14.782892 | S5: =+J5/$C5 -> 22.965436 | T5: =+K5/$C5 -> 0.21137804 | U5: =+L5/$C5 -> 0
B6: อ.บางน้ำเปรี้ยว | C6: =SUMIFS(Data!$Y$2:$Y$2000,Data!$E$2:$E$2000,WeightCal!B6) -> 4.967855e+08 | D6: =SUMIFS(Data!AA$2:AA$2000,Data!$E$2:$E$2000,WeightCal!$B6) -> 6.8563189e+09 | E6: =SUMIFS(Data!AB$2:AB$2000,Data!$E$2:$E$2000,WeightCal!$B6) -> 61567490 | F6: =SUMIFS(Data!AC$2:AC$2000,Data!$E$2:$E$2000,WeightCal!$B6) -> 1.4793032e+10 | G6: =SUMIFS(Data!AD$2:AD$2000,Data!$E$2:$E$2000,WeightCal!$B6) -> 3.9370316e+08 | H6: =SUMIFS(Data!AE$2:AE$2000,Data!$E$2:$E$2000,WeightCal!$B6) -> 2.6503505e+08 | I6: =SUMIFS(Data!AF$2:AF$2000,Data!$E$2:$E$2000,WeightCal!$B6) -> 6.5587319e+09 | J6: =SUMIFS(Data!AG$2:AG$2000,Data!$E$2:$E$2000,WeightCal!$B6) -> 3.1048216e+09 | K6: =SUMIFS(Data!AH$2:AH$2000,Data!$E$2:$E$2000,WeightCal!$B6) -> 0 | L6: =SUMIFS(Data!AI$2:AI$2000,Data!$E$2:$E$2000,WeightCal!$B6) -> 0 | M6: =+D6/$C6 -> 13.801367 | N6: =+E6/$C6 -> 0.12393174 | O6: =+F6/$C6 -> 29.777503 | P6: =+G6/$C6 -> 0.79250131 | Q6: =+H6/$C6 -> 0.53349998 | R6: =+I6/$C6 -> 13.202342 | S6: =+J6/$C6 -> 6.2498233 | T6: =+K6/$C6 -> 0 | U6: =+L6/$C6 -> 0
B7: อ.บางปะกง | C7: =SUMIFS(Data!$Y$2:$Y$2000,Data!$E$2:$E$2000,WeightCal!B7) -> 2.6035699e+08 | D7: =SUMIFS(Data!AA$2:AA$2000,Data!$E$2:$E$2000,WeightCal!$B7) -> 1.3108266e+09 | E7: =SUMIFS(Data!AB$2:AB$2000,Data!$E$2:$E$2000,WeightCal!$B7) -> 1.3802798e+09 | F7: =SUMIFS(Data!AC$2:AC$2000,Data!$E$2:$E$2000,WeightCal!$B7) -> 5.0965627e+08 | G7: =SUMIFS(Data!AD$2:AD$2000,Data!$E$2:$E$2000,WeightCal!$B7) -> 2.8042975e+09 | H7: =SUMIFS(Data!AE$2:AE$2000,Data!$E$2:$E$2000,WeightCal!$B7) -> 7.9115991e+08 | I7: =SUMIFS(Data!AF$2:AF$2000,Data!$E$2:$E$2000,WeightCal!$B7) -> 4.8948118e+09 | J7: =SUMIFS(Data!AG$2:AG$2000,Data!$E$2:$E$2000,WeightCal!$B7) -> 2.407787e+09 | K7: =SUMIFS(Data!AH$2:AH$2000,Data!$E$2:$E$2000,WeightCal!$B7) -> 45668354 | L7: =SUMIFS(Data!AI$2:AI$2000,Data!$E$2:$E$2000,WeightCal!$B7) -> 0 | M7: =+D7/$C7 -> 5.034728 | N7: =+E7/$C7 -> 5.3014893 | O7: =+F7/$C7 -> 1.9575286 | P7: =+G7/$C7 -> 10.770971 | Q7: =+H7/$C7 -> 3.0387504 | R7: =+I7/$C7 -> 18.800386 | S7: =+J7/$C7 -> 9.2480215 | T7: =+K7/$C7 -> 0.17540667 | U7: =+L7/$C7 -> 0
B8: อ.บ้านโพธิ์ | C8: =SUMIFS(Data!$Y$2:$Y$2000,Data!$E$2:$E$2000,WeightCal!B8) -> 2.1124006e+08 | D8: =SUMIFS(Data!AA$2:AA$2000,Data!$E$2:$E$2000,WeightCal!$B8) -> 2.742625e+09 | E8: =SUMIFS(Data!AB$2:AB$2000,Data!$E$2:$E$2000,WeightCal!$B8) -> 2.0484891e+08 | F8: =SUMIFS(Data!AC$2:AC$2000,Data!$E$2:$E$2000,WeightCal!$B8) -> 3.5268615e+08 | G8: =SUMIFS(Data!AD$2:AD$2000,Data!$E$2:$E$2000,WeightCal!$B8) -> 9.0961697e+08 | H8: =SUMIFS(Data!AE$2:AE$2000,Data!$E$2:$E$2000,WeightCal!$B8) -> 2.7597615e+08 | I8: =SUMIFS(Data!AF$2:AF$2000,Data!$E$2:$E$2000,WeightCal!$B8) -> 2.2298912e+09 | J8: =SUMIFS(Data!AG$2:AG$2000,Data!$E$2:$E$2000,WeightCal!$B8) -> 3.5812461e+09 | K8: =SUMIFS(Data!AH$2:AH$2000,Data!$E$2:$E$2000,WeightCal!$B8) -> 31609483 | L8: =SUMIFS(Data!AI$2:AI$2000,Data!$E$2:$E$2000,WeightCal!$B8) -> 150134.54 | M8: =+D8/$C8 -> 12.983452 | N8: =+E8/$C8 -> 0.96974465 | O8: =+F8/$C8 -> 1.6695988 | P8: =+G8/$C8 -> 4.3060819 | Q8: =+H8/$C8 -> 1.3064575 | R8: =+I8/$C8 -> 10.556195 | S8: =+J8/$C8 -> 16.953443 | T8: =+K8/$C8 -> 0.14963773 | U8: =+L8/$C8 -> 0.0007107295
B9: อ.แปลงยาว | C9: =SUMIFS(Data!$Y$2:$Y$2000,Data!$E$2:$E$2000,WeightCal!B9) -> 3.2790539e+08 | D9: =SUMIFS(Data!AA$2:AA$2000,Data!$E$2:$E$2000,WeightCal!$B9) -> 1.3071768e+10 | E9: =SUMIFS(Data!AB$2:AB$2000,Data!$E$2:$E$2000,WeightCal!$B9) -> 9.1672446e+08 | F9: =SUMIFS(Data!AC$2:AC$2000,Data!$E$2:$E$2000,WeightCal!$B9) -> 1.9475437e+08 | G9: =SUMIFS(Data!AD$2:AD$2000,Data!$E$2:$E$2000,WeightCal!$B9) -> 7.9680682e+08 | H9: =SUMIFS(Data!AE$2:AE$2000,Data!$E$2:$E$2000,WeightCal!$B9) -> 6.1954337e+08 | I9: =SUMIFS(Data!AF$2:AF$2000,Data!$E$2:$E$2000,WeightCal!$B9) -> 4.3265589e+09 | J9: =SUMIFS(Data!AG$2:AG$2000,Data!$E$2:$E$2000,WeightCal!$B9) -> 6.5766213e+09 | K9: =SUMIFS(Data!AH$2:AH$2000,Data!$E$2:$E$2000,WeightCal!$B9) -> 74719780 | L9: =SUMIFS(Data!AI$2:AI$2000,Data!$E$2:$E$2000,WeightCal!$B9) -> 5335641.1 | M9: =+D9/$C9 -> 39.864449 | N9: =+E9/$C9 -> 2.7956981 | O9: =+F9/$C9 -> 0.59393463 | P9: =+G9/$C9 -> 2.42999 | Q9: =+H9/$C9 -> 1.8893967 | R9: =+I9/$C9 -> 13.194534 | S9: =+J9/$C9 -> 20.05646 | T9: =+K9/$C9 -> 0.22786994 | U9: =+L9/$C9 -> 0.016271892
B10: อ.พนมสารคาม | C10: =SUMIFS(Data!$Y$2:$Y$2000,Data!$E$2:$E$2000,WeightCal!B10) -> 5.1125265e+08 | D10: =SUMIFS(Data!AA$2:AA$2000,Data!$E$2:$E$2000,WeightCal!$B10) -> 8.1162639e+09 | E10: =SUMIFS(Data!AB$2:AB$2000,Data!$E$2:$E$2000,WeightCal!$B10) -> 2.0385709e+09 | F10: =SUMIFS(Data!AC$2:AC$2000,Data!$E$2:$E$2000,WeightCal!$B10) -> 3.4900988e+09 | G10: =SUMIFS(Data!AD$2:AD$2000,Data!$E$2:$E$2000,WeightCal!$B10) -> 2.6764453e+09 | H10: =SUMIFS(Data!AE$2:AE$2000,Data!$E$2:$E$2000,WeightCal!$B10) -> 5.7494504e+08 | I10: =SUMIFS(Data!AF$2:AF$2000,Data!$E$2:$E$2000,WeightCal!$B10) -> 5.7316137e+09 | J10: =SUMIFS(Data!AG$2:AG$2000,Data!$E$2:$E$2000,WeightCal!$B10) -> 4.8287676e+09 | K10: =SUMIFS(Data!AH$2:AH$2000,Data!$E$2:$E$2000,WeightCal!$B10) -> 3.2991419e+09 | L10: =SUMIFS(Data!AI$2:AI$2000,Data!$E$2:$E$2000,WeightCal!$B10) -> 23644648 | M10: =+D10/$C10 -> 15.875251 | N10: =+E10/$C10 -> 3.987404 | O10: =+F10/$C10 -> 6.8265637 | P10: =+G10/$C10 -> 5.2350737 | Q10: =+H10/$C10 -> 1.124581 | R10: =+I10/$C10 -> 11.210922 | S10: =+J10/$C10 -> 9.4449733 | T10: =+K10/$C10 -> 6.4530558 | U10: =+L10/$C10 -> 0.04624846
B11: อ.เมืองฉะเชิงเทรา | C11: =SUMIFS(Data!$Y$2:$Y$2000,Data!$E$2:$E$2000,WeightCal!B11) -> 3.8509365e+08 | D11: =SUMIFS(Data!AA$2:AA$2000,Data!$E$2:$E$2000,WeightCal!$B11) -> 5.8909652e+09 | E11: =SUMIFS(Data!AB$2:AB$2000,Data!$E$2:$E$2000,WeightCal!$B11) -> 3.4696614e+08 | F11: =SUMIFS(Data!AC$2:AC$2000,Data!$E$2:$E$2000,WeightCal!$B11) -> 4.4769342e+09 | G11: =SUMIFS(Data!AD$2:AD$2000,Data!$E$2:$E$2000,WeightCal!$B11) -> 7.1433449e+08 | H11: =SUMIFS(Data!AE$2:AE$2000,Data!$E$2:$E$2000,WeightCal!$B11) -> 6.6563853e+08 | I11: =SUMIFS(Data!AF$2:AF$2000,Data!$E$2:$E$2000,WeightCal!$B11) -> 5.8612666e+09 | J11: =SUMIFS(Data!AG$2:AG$2000,Data!$E$2:$E$2000,WeightCal!$B11) -> 7.387994e+09 | K11: =SUMIFS(Data!AH$2:AH$2000,Data!$E$2:$E$2000,WeightCal!$B11) -> 38971153 | L11: =SUMIFS(Data!AI$2:AI$2000,Data!$E$2:$E$2000,WeightCal!$B11) -> 0 | M11: =+D11/$C11 -> 15.297487 | N11: =+E11/$C11 -> 0.90099159 | O11: =+F11/$C11 -> 11.625573 | P11: =+G11/$C11 -> 1.854963 | Q11: =+H11/$C11 -> 1.7285108 | R11: =+I11/$C11 -> 15.220367 | S11: =+J11/$C11 -> 19.184928 | T11: =+K11/$C11 -> 0.10119916 | U11: =+L11/$C11 -> 0
B12: อ.ราชสาส์น | C12: =SUMIFS(Data!$Y$2:$Y$2000,Data!$E$2:$E$2000,WeightCal!B12) -> 1.4476785e+08 | D12: =SUMIFS(Data!AA$2:AA$2000,Data!$E$2:$E$2000,WeightCal!$B12) -> 4.6175729e+09 | E12: =SUMIFS(Data!AB$2:AB$2000,Data!$E$2:$E$2000,WeightCal!$B12) -> 5.7045864e+08 | F12: =SUMIFS(Data!AC$2:AC$2000,Data!$E$2:$E$2000,WeightCal!$B12) -> 1.4185215e+09 | G12: =SUMIFS(Data!AD$2:AD$2000,Data!$E$2:$E$2000,WeightCal!$B12) -> 7177215.5 | H12: =SUMIFS(Data!AE$2:AE$2000,Data!$E$2:$E$2000,WeightCal!$B12) -> 88829892 | I12: =SUMIFS(Data!AF$2:AF$2000,Data!$E$2:$E$2000,WeightCal!$B12) -> 1.3762774e+09 | J12: =SUMIFS(Data!AG$2:AG$2000,Data!$E$2:$E$2000,WeightCal!$B12) -> 2.6725269e+09 | K12: =SUMIFS(Data!AH$2:AH$2000,Data!$E$2:$E$2000,WeightCal!$B12) -> 62586105 | L12: =SUMIFS(Data!AI$2:AI$2000,Data!$E$2:$E$2000,WeightCal!$B12) -> 354734.82 | M12: =+D12/$C12 -> 31.896397 | N12: =+E12/$C12 -> 3.9405064 | O12: =+F12/$C12 -> 9.798595 | P12: =+G12/$C12 -> 0.049577412 | Q12: =+H12/$C12 -> 0.61360234 | R12: =+I12/$C12 -> 9.506789 | S12: =+J12/$C12 -> 18.460776 | T12: =+K12/$C12 -> 0.43232046 | U12: =+L12/$C12 -> 0.0024503702
B13: อ.สนามชัยเขต | C13: =SUMIFS(Data!$Y$2:$Y$2000,Data!$E$2:$E$2000,WeightCal!B13) -> 1.0670447e+09 | D13: =SUMIFS(Data!AA$2:AA$2000,Data!$E$2:$E$2000,WeightCal!$B13) -> 5.3319295e+09 | E13: =SUMIFS(Data!AB$2:AB$2000,Data!$E$2:$E$2000,WeightCal!$B13) -> 8.4755156e+09 | F13: =SUMIFS(Data!AC$2:AC$2000,Data!$E$2:$E$2000,WeightCal!$B13) -> 1.8099964e+09 | G13: =SUMIFS(Data!AD$2:AD$2000,Data!$E$2:$E$2000,WeightCal!$B13) -> 4.262496e+08 | H13: =SUMIFS(Data!AE$2:AE$2000,Data!$E$2:$E$2000,WeightCal!$B13) -> 9.8828028e+08 | I13: =SUMIFS(Data!AF$2:AF$2000,Data!$E$2:$E$2000,WeightCal!$B13) -> 8.6549021e+09 | J13: =SUMIFS(Data!AG$2:AG$2000,Data!$E$2:$E$2000,WeightCal!$B13) -> 1.5916315e+10 | K13: =SUMIFS(Data!AH$2:AH$2000,Data!$E$2:$E$2000,WeightCal!$B13) -> 6.3273907e+08 | L13: =SUMIFS(Data!AI$2:AI$2000,Data!$E$2:$E$2000,WeightCal!$B13) -> 94657112 | M13: =+D13/$C13 -> 4.9969129 | N13: =+E13/$C13 -> 7.9429809 | O13: =+F13/$C13 -> 1.6962705 | P13: =+G13/$C13 -> 0.39946743 | Q13: =+H13/$C13 -> 0.92618452 | R13: =+I13/$C13 -> 8.1110961 | S13: =+J13/$C13 -> 14.916259 | T13: =+K13/$C13 -> 0.59298272 | U13: =+L13/$C13 -> 0.088709603
A14: จ.ชลบุรี | B14: อ.เกาะจันทร์ | C14: =SUMIFS(Data!$Y$2:$Y$2000,Data!$E$2:$E$2000,WeightCal!B14) -> 2.6920651e+08 | D14: =SUMIFS(Data!AA$2:AA$2000,Data!$E$2:$E$2000,WeightCal!$B14) -> 3.4987933e+09 | E14: =SUMIFS(Data!AB$2:AB$2000,Data!$E$2:$E$2000,WeightCal!$B14) -> 12067107 | F14: =SUMIFS(Data!AC$2:AC$2000,Data!$E$2:$E$2000,WeightCal!$B14) -> 1.99949e+08 | G14: =SUMIFS(Data!AD$2:AD$2000,Data!$E$2:$E$2000,WeightCal!$B14) -> 4.0027333e+08 | H14: =SUMIFS(Data!AE$2:AE$2000,Data!$E$2:$E$2000,WeightCal!$B14) -> 1.8778923e+08 | I14: =SUMIFS(Data!AF$2:AF$2000,Data!$E$2:$E$2000,WeightCal!$B14) -> 3.1440172e+09 | J14: =SUMIFS(Data!AG$2:AG$2000,Data!$E$2:$E$2000,WeightCal!$B14) -> 2.2959935e+09 | K14: =SUMIFS(Data!AH$2:AH$2000,Data!$E$2:$E$2000,WeightCal!$B14) -> 1502547.6 | L14: =SUMIFS(Data!AI$2:AI$2000,Data!$E$2:$E$2000,WeightCal!$B14) -> 0 | M14: =+D14/$C14 -> 12.996689 | N14: =+E14/$C14 -> 0.044824721 | O14: =+F14/$C14 -> 0.74273465 | P14: =+G14/$C14 -> 1.4868635 | Q14: =+H14/$C14 -> 0.6975657 | R14: =+I14/$C14 -> 11.678831 | S14: =+J14/$C14 -> 8.5287444 | T14: =+K14/$C14 -> 0.0055813941 | U14: =+L14/$C14 -> 0
B15: อ.บ่อทอง | C15: =SUMIFS(Data!$Y$2:$Y$2000,Data!$E$2:$E$2000,WeightCal!B15) -> 8.325686e+08 | D15: =SUMIFS(Data!AA$2:AA$2000,Data!$E$2:$E$2000,WeightCal!$B15) -> 2.0115586e+09 | E15: =SUMIFS(Data!AB$2:AB$2000,Data!$E$2:$E$2000,WeightCal!$B15) -> 2.5161269e+08 | F15: =SUMIFS(Data!AC$2:AC$2000,Data!$E$2:$E$2000,WeightCal!$B15) -> 1.3996676e+09 | G15: =SUMIFS(Data!AD$2:AD$2000,Data!$E$2:$E$2000,WeightCal!$B15) -> 2.7081909e+09 | H15: =SUMIFS(Data!AE$2:AE$2000,Data!$E$2:$E$2000,WeightCal!$B15) -> 4.8447367e+09 | I15: =SUMIFS(Data!AF$2:AF$2000,Data!$E$2:$E$2000,WeightCal!$B15) -> 1.826222e+10 | J15: =SUMIFS(Data!AG$2:AG$2000,Data!$E$2:$E$2000,WeightCal!$B15) -> 9.0823201e+09 | K15: =SUMIFS(Data!AH$2:AH$2000,Data!$E$2:$E$2000,WeightCal!$B15) -> 3.2939866e+09 | L15: =SUMIFS(Data!AI$2:AI$2000,Data!$E$2:$E$2000,WeightCal!$B15) -> 66472935 | M15: =+D15/$C15 -> 2.4160875 | N15: =+E15/$C15 -> 0.30221256 | O15: =+F15/$C15 -> 1.6811438 | P15: =+G15/$C15 -> 3.2528141 | Q15: =+H15/$C15 -> 5.819024 | R15: =+I15/$C15 -> 21.934793 | S15: =+J15/$C15 -> 10.908795 | T15: =+K15/$C15 -> 3.9564146 | U15: =+L15/$C15 -> 0.07984079
B16: อ.บางละมุง | C16: =SUMIFS(Data!$Y$2:$Y$2000,Data!$E$2:$E$2000,WeightCal!B16) -> 5.3621023e+08 | D16: =SUMIFS(Data!AA$2:AA$2000,Data!$E$2:$E$2000,WeightCal!$B16) -> 4.0401035e+08 | E16: =SUMIFS(Data!AB$2:AB$2000,Data!$E$2:$E$2000,WeightCal!$B16) -> 1.5353011e+09 | F16: =SUMIFS(Data!AC$2:AC$2000,Data!$E$2:$E$2000,WeightCal!$B16) -> 1.0391161e+09 | G16: =SUMIFS(Data!AD$2:AD$2000,Data!$E$2:$E$2000,WeightCal!$B16) -> 1.205804e+08 | H16: =SUMIFS(Data!AE$2:AE$2000,Data!$E$2:$E$2000,WeightCal!$B16) -> 1.8902197e+09 | I16: =SUMIFS(Data!AF$2:AF$2000,Data!$E$2:$E$2000,WeightCal!$B16) -> 1.4630834e+10 | J16: =SUMIFS(Data!AG$2:AG$2000,Data!$E$2:$E$2000,WeightCal!$B16) -> 4.6278116e+09 | K16: =SUMIFS(Data!AH$2:AH$2000,Data!$E$2:$E$2000,WeightCal!$B16) -> 1.3659775e+10 | L16: =SUMIFS(Data!AI$2:AI$2000,Data!$E$2:$E$2000,WeightCal!$B16) -> 1.8746728e+09 | M16: =+D16/$C16 -> 0.75345514 | N16: =+E16/$C16 -> 2.8632447 | O16: =+F16/$C16 -> 1.9378894 | P16: =+G16/$C16 -> 0.22487523 | Q16: =+H16/$C16 -> 3.5251466 | R16: =+I16/$C16 -> 27.28563 | S16: =+J16/$C16 -> 8.6305919 | T16: =+K16/$C16 -> 25.474663 | U16: =+L16/$C16 -> 3.4961527
B17: อ.บ้านบึง | C17: =SUMIFS(Data!$Y$2:$Y$2000,Data!$E$2:$E$2000,WeightCal!B17) -> 5.9341059e+08 | D17: =SUMIFS(Data!AA$2:AA$2000,Data!$E$2:$E$2000,WeightCal!$B17) -> 5.0135492e+08 | E17: =SUMIFS(Data!AB$2:AB$2000,Data!$E$2:$E$2000,WeightCal!$B17) -> 3.6529673e+09 | F17: =SUMIFS(Data!AC$2:AC$2000,Data!$E$2:$E$2000,WeightCal!$B17) -> 4.2843461e+09 | G17: =SUMIFS(Data!AD$2:AD$2000,Data!$E$2:$E$2000,WeightCal!$B17) -> 4.0026558e+09 | H17: =SUMIFS(Data!AE$2:AE$2000,Data!$E$2:$E$2000,WeightCal!$B17) -> 1.6225642e+08 | I17: =SUMIFS(Data!AF$2:AF$2000,Data!$E$2:$E$2000,WeightCal!$B17) -> 3.2621552e+10 | J17: =SUMIFS(Data!AG$2:AG$2000,Data!$E$2:$E$2000,WeightCal!$B17) -> 2.5560174e+09 | K17: =SUMIFS(Data!AH$2:AH$2000,Data!$E$2:$E$2000,WeightCal!$B17) -> 9.3112517e+08 | L17: =SUMIFS(Data!AI$2:AI$2000,Data!$E$2:$E$2000,WeightCal!$B17) -> 0 | M17: =+D17/$C17 -> 0.8448702 | N17: =+E17/$C17 -> 6.1558849 | O17: =+F17/$C17 -> 7.219868 | P17: =+G17/$C17 -> 6.7451709 | Q17: =+H17/$C17 -> 0.27343027 | R17: =+I17/$C17 -> 54.972986 | S17: =+J17/$C17 -> 4.3073337 | T17: =+K17/$C17 -> 1.5691078 | U17: =+L17/$C17 -> 0
B18: อ.พนัสนิคม | C18: =SUMIFS(Data!$Y$2:$Y$2000,Data!$E$2:$E$2000,WeightCal!B18) -> 4.7966736e+08 | D18: =SUMIFS(Data!AA$2:AA$2000,Data!$E$2:$E$2000,WeightCal!$B18) -> 4.0029469e+09 | E18: =SUMIFS(Data!AB$2:AB$2000,Data!$E$2:$E$2000,WeightCal!$B18) -> 1.9013548e+09 | F18: =SUMIFS(Data!AC$2:AC$2000,Data!$E$2:$E$2000,WeightCal!$B18) -> 1.0152427e+09 | G18: =SUMIFS(Data!AD$2:AD$2000,Data!$E$2:$E$2000,WeightCal!$B18) -> 4.4110631e+09 | H18: =SUMIFS(Data!AE$2:AE$2000,Data!$E$2:$E$2000,WeightCal!$B18) -> 2.9799935e+08 | I18: =SUMIFS(Data!AF$2:AF$2000,Data!$E$2:$E$2000,WeightCal!$B18) -> 9.2223505e+09 | J18: =SUMIFS(Data!AG$2:AG$2000,Data!$E$2:$E$2000,WeightCal!$B18) -> 1.7521694e+09 | K18: =SUMIFS(Data!AH$2:AH$2000,Data!$E$2:$E$2000,WeightCal!$B18) -> 3208376.5 | L18: =SUMIFS(Data!AI$2:AI$2000,Data!$E$2:$E$2000,WeightCal!$B18) -> 39987.975 | M18: =+D18/$C18 -> 8.3452559 | N18: =+E18/$C18 -> 3.9639028 | O18: =+F18/$C18 -> 2.1165558 | P18: =+G18/$C18 -> 9.1960875 | Q18: =+H18/$C18 -> 0.6212625 | R18: =+I18/$C18 -> 19.226554 | S18: =+J18/$C18 -> 3.6528844 | T18: =+K18/$C18 -> 0.0066887529 | U18: =+L18/$C18 -> 8.3366053e-05
B19: อ.พานทอง | C19: =SUMIFS(Data!$Y$2:$Y$2000,Data!$E$2:$E$2000,WeightCal!B19) -> 1.6774727e+08 | D19: =SUMIFS(Data!AA$2:AA$2000,Data!$E$2:$E$2000,WeightCal!$B19) -> 3.4982095e+08 | E19: =SUMIFS(Data!AB$2:AB$2000,Data!$E$2:$E$2000,WeightCal!$B19) -> 4.7098422e+09 | F19: =SUMIFS(Data!AC$2:AC$2000,Data!$E$2:$E$2000,WeightCal!$B19) -> 1.7748163e+09 | G19: =SUMIFS(Data!AD$2:AD$2000,Data!$E$2:$E$2000,WeightCal!$B19) -> 5.3080756e+08 | H19: =SUMIFS(Data!AE$2:AE$2000,Data!$E$2:$E$2000,WeightCal!$B19) -> 44124480 | I19: =SUMIFS(Data!AF$2:AF$2000,Data!$E$2:$E$2000,WeightCal!$B19) -> 8.9901803e+09 | J19: =SUMIFS(Data!AG$2:AG$2000,Data!$E$2:$E$2000,WeightCal!$B19) -> 3.9447711e+08 | K19: =SUMIFS(Data!AH$2:AH$2000,Data!$E$2:$E$2000,WeightCal!$B19) -> 38123.982 | L19: =SUMIFS(Data!AI$2:AI$2000,Data!$E$2:$E$2000,WeightCal!$B19) -> 0 | M19: =+D19/$C19 -> 2.0854047 | N19: =+E19/$C19 -> 28.077012 | O19: =+F19/$C19 -> 10.580299 | P19: =+G19/$C19 -> 3.164329 | Q19: =+H19/$C19 -> 0.26304141 | R19: =+I19/$C19 -> 53.5936 | S19: =+J19/$C19 -> 2.3516156 | T19: =+K19/$C19 -> 0.00022727035 | U19: =+L19/$C19 -> 0
B20: อ.เมืองชลบุรี | C20: =SUMIFS(Data!$Y$2:$Y$2000,Data!$E$2:$E$2000,WeightCal!B20) -> 2.5567368e+08 | D20: =SUMIFS(Data!AA$2:AA$2000,Data!$E$2:$E$2000,WeightCal!$B20) -> 3.9423846e+08 | E20: =SUMIFS(Data!AB$2:AB$2000,Data!$E$2:$E$2000,WeightCal!$B20) -> 3.5936384e+09 | F20: =SUMIFS(Data!AC$2:AC$2000,Data!$E$2:$E$2000,WeightCal!$B20) -> 1.5381855e+09 | G20: =SUMIFS(Data!AD$2:AD$2000,Data!$E$2:$E$2000,WeightCal!$B20) -> 7.2457754e+08 | H20: =SUMIFS(Data!AE$2:AE$2000,Data!$E$2:$E$2000,WeightCal!$B20) -> 2.9694574e+08 | I20: =SUMIFS(Data!AF$2:AF$2000,Data!$E$2:$E$2000,WeightCal!$B20) -> 9.1022117e+09 | J20: =SUMIFS(Data!AG$2:AG$2000,Data!$E$2:$E$2000,WeightCal!$B20) -> 1.0027192e+09 | K20: =SUMIFS(Data!AH$2:AH$2000,Data!$E$2:$E$2000,WeightCal!$B20) -> 94951063 | L20: =SUMIFS(Data!AI$2:AI$2000,Data!$E$2:$E$2000,WeightCal!$B20) -> 3991003.9 | M20: =+D20/$C20 -> 1.5419595 | N20: =+E20/$C20 -> 14.055567 | O20: =+F20/$C20 -> 6.016206 | P20: =+G20/$C20 -> 2.8339935 | Q20: =+H20/$C20 -> 1.1614248 | R20: =+I20/$C20 -> 35.600895 | S20: =+J20/$C20 -> 3.9218711 | T20: =+K20/$C20 -> 0.37137598 | U20: =+L20/$C20 -> 0.015609757
B21: อ.ศรีราชา | C21: =SUMIFS(Data!$Y$2:$Y$2000,Data!$E$2:$E$2000,WeightCal!B21) -> 6.2371544e+08 | D21: =SUMIFS(Data!AA$2:AA$2000,Data!$E$2:$E$2000,WeightCal!$B21) -> 1.6099859e+09 | E21: =SUMIFS(Data!AB$2:AB$2000,Data!$E$2:$E$2000,WeightCal!$B21) -> 1.2907275e+09 | F21: =SUMIFS(Data!AC$2:AC$2000,Data!$E$2:$E$2000,WeightCal!$B21) -> 5.8898247e+09 | G21: =SUMIFS(Data!AD$2:AD$2000,Data!$E$2:$E$2000,WeightCal!$B21) -> 2.1884199e+09 | H21: =SUMIFS(Data!AE$2:AE$2000,Data!$E$2:$E$2000,WeightCal!$B21) -> 2.9734963e+08 | I21: =SUMIFS(Data!AF$2:AF$2000,Data!$E$2:$E$2000,WeightCal!$B21) -> 2.8326283e+10 | J21: =SUMIFS(Data!AG$2:AG$2000,Data!$E$2:$E$2000,WeightCal!$B21) -> 2.5287105e+09 | K21: =SUMIFS(Data!AH$2:AH$2000,Data!$E$2:$E$2000,WeightCal!$B21) -> 3.8554259e+09 | L21: =SUMIFS(Data!AI$2:AI$2000,Data!$E$2:$E$2000,WeightCal!$B21) -> 1.1307139e+08 | M21: =+D21/$C21 -> 2.5812828 | N21: =+E21/$C21 -> 2.0694172 | O21: =+F21/$C21 -> 9.4431278 | P21: =+G21/$C21 -> 3.5086832 | Q21: =+H21/$C21 -> 0.47673925 | R21: =+I21/$C21 -> 45.415394 | S21: =+J21/$C21 -> 4.0542695 | T21: =+K21/$C21 -> 6.181386 | U21: =+L21/$C21 -> 0.18128682
B22: อ.สัตหีบ | C22: =SUMIFS(Data!$Y$2:$Y$2000,Data!$E$2:$E$2000,WeightCal!B22) -> 2.8712297e+08 | D22: =SUMIFS(Data!AA$2:AA$2000,Data!$E$2:$E$2000,WeightCal!$B22) -> 4.8132414e+08 | E22: =SUMIFS(Data!AB$2:AB$2000,Data!$E$2:$E$2000,WeightCal!$B22) -> 4.8159927e+08 | F22: =SUMIFS(Data!AC$2:AC$2000,Data!$E$2:$E$2000,WeightCal!$B22) -> 1.8605544e+08 | G22: =SUMIFS(Data!AD$2:AD$2000,Data!$E$2:$E$2000,WeightCal!$B22) -> 2.9190504e+08 | H22: =SUMIFS(Data!AE$2:AE$2000,Data!$E$2:$E$2000,WeightCal!$B22) -> 4.9919759e+08 | I22: =SUMIFS(Data!AF$2:AF$2000,Data!$E$2:$E$2000,WeightCal!$B22) -> 6.6201045e+09 | J22: =SUMIFS(Data!AG$2:AG$2000,Data!$E$2:$E$2000,WeightCal!$B22) -> 3.158891e+09 | K22: =SUMIFS(Data!AH$2:AH$2000,Data!$E$2:$E$2000,WeightCal!$B22) -> 2.3776123e+09 | L22: =SUMIFS(Data!AI$2:AI$2000,Data!$E$2:$E$2000,WeightCal!$B22) -> 1.8815744e+09 | M22: =+D22/$C22 -> 1.6763694 | N22: =+E22/$C22 -> 1.6773276 | O22: =+F22/$C22 -> 0.64799917 | P22: =+G22/$C22 -> 1.0166552 | Q22: =+H22/$C22 -> 1.7386195 | R22: =+I22/$C22 -> 23.056687 | S22: =+J22/$C22 -> 11.001875 | T22: =+K22/$C22 -> 8.2808154 | U22: =+L22/$C22 -> 6.5532007
B23: อ.หนองใหญ่ | C23: =SUMIFS(Data!$Y$2:$Y$2000,Data!$E$2:$E$2000,WeightCal!B23) -> 4.5600546e+08 | D23: =SUMIFS(Data!AA$2:AA$2000,Data!$E$2:$E$2000,WeightCal!$B23) -> 4.462035e+08 | E23: =SUMIFS(Data!AB$2:AB$2000,Data!$E$2:$E$2000,WeightCal!$B23) -> 6.431762e+08 | F23: =SUMIFS(Data!AC$2:AC$2000,Data!$E$2:$E$2000,WeightCal!$B23) -> 3.8364388e+08 | G23: =SUMIFS(Data!AD$2:AD$2000,Data!$E$2:$E$2000,WeightCal!$B23) -> 6.7683076e+08 | H23: =SUMIFS(Data!AE$2:AE$2000,Data!$E$2:$E$2000,WeightCal!$B23) -> 2.7663745e+09 | I23: =SUMIFS(Data!AF$2:AF$2000,Data!$E$2:$E$2000,WeightCal!$B23) -> 1.2381638e+10 | J23: =SUMIFS(Data!AG$2:AG$2000,Data!$E$2:$E$2000,WeightCal!$B23) -> 2.8085182e+09 | K23: =SUMIFS(Data!AH$2:AH$2000,Data!$E$2:$E$2000,WeightCal!$B23) -> 2.8068742e+09 | L23: =SUMIFS(Data!AI$2:AI$2000,Data!$E$2:$E$2000,WeightCal!$B23) -> 28652665 | M23: =+D23/$C23 -> 0.97850473 | N23: =+E23/$C23 -> 1.4104572 | O23: =+F23/$C23 -> 0.84131422 | P23: =+G23/$C23 -> 1.4842602 | Q23: =+H23/$C23 -> 6.0665381 | R23: =+I23/$C23 -> 27.15239 | S23: =+J23/$C23 -> 6.1589574 | T23: =+K23/$C23 -> 6.1553522 | U23: =+L23/$C23 -> 0.062834039
A24: จ.ระยอง | B24: อ.แกลง | C24: =SUMIFS(Data!$Y$2:$Y$2000,Data!$E$2:$E$2000,WeightCal!B24) -> 7.357859e+08 | D24: =SUMIFS(Data!AA$2:AA$2000,Data!$E$2:$E$2000,WeightCal!$B24) -> 1.2792614e+09 | E24: =SUMIFS(Data!AB$2:AB$2000,Data!$E$2:$E$2000,WeightCal!$B24) -> 81727326 | F24: =SUMIFS(Data!AC$2:AC$2000,Data!$E$2:$E$2000,WeightCal!$B24) -> 1.3201095e+09 | G24: =SUMIFS(Data!AD$2:AD$2000,Data!$E$2:$E$2000,WeightCal!$B24) -> 8.1486559e+09 | H24: =SUMIFS(Data!AE$2:AE$2000,Data!$E$2:$E$2000,WeightCal!$B24) -> 1.2565594e+09 | I24: =SUMIFS(Data!AF$2:AF$2000,Data!$E$2:$E$2000,WeightCal!$B24) -> 7.314987e+09 | J24: =SUMIFS(Data!AG$2:AG$2000,Data!$E$2:$E$2000,WeightCal!$B24) -> 7.0293465e+09 | K24: =SUMIFS(Data!AH$2:AH$2000,Data!$E$2:$E$2000,WeightCal!$B24) -> 1.3544837e+10 | L24: =SUMIFS(Data!AI$2:AI$2000,Data!$E$2:$E$2000,WeightCal!$B24) -> 3.9488972e+09 | M24: =+D24/$C24 -> 1.7386327 | N24: =+E24/$C24 -> 0.11107487 | O24: =+F24/$C24 -> 1.7941489 | P24: =+G24/$C24 -> 11.074765 | Q24: =+H24/$C24 -> 1.7077785 | R24: =+I24/$C24 -> 9.941733 | S24: =+J24/$C24 -> 9.5535216 | T24: =+K24/$C24 -> 18.408666 | U24: =+L24/$C24 -> 5.3669106
B25: อ.เขาชะเมา | C25: =SUMIFS(Data!$Y$2:$Y$2000,Data!$E$2:$E$2000,WeightCal!B25) -> 4.770012e+08 | D25: =SUMIFS(Data!AA$2:AA$2000,Data!$E$2:$E$2000,WeightCal!$B25) -> 6.7067438e+09 | E25: =SUMIFS(Data!AB$2:AB$2000,Data!$E$2:$E$2000,WeightCal!$B25) -> 35042046 | F25: =SUMIFS(Data!AC$2:AC$2000,Data!$E$2:$E$2000,WeightCal!$B25) -> 1.2203778e+08 | G25: =SUMIFS(Data!AD$2:AD$2000,Data!$E$2:$E$2000,WeightCal!$B25) -> 1.75225e+09 | H25: =SUMIFS(Data!AE$2:AE$2000,Data!$E$2:$E$2000,WeightCal!$B25) -> 9.3531127e+09 | I25: =SUMIFS(Data!AF$2:AF$2000,Data!$E$2:$E$2000,WeightCal!$B25) -> 3.4341947e+09 | J25: =SUMIFS(Data!AG$2:AG$2000,Data!$E$2:$E$2000,WeightCal!$B25) -> 5.0899432e+09 | K25: =SUMIFS(Data!AH$2:AH$2000,Data!$E$2:$E$2000,WeightCal!$B25) -> 1.8623786e+09 | L25: =SUMIFS(Data!AI$2:AI$2000,Data!$E$2:$E$2000,WeightCal!$B25) -> 1.0997568e+08 | M25: =+D25/$C25 -> 14.060224 | N25: =+E25/$C25 -> 0.073463224 | O25: =+F25/$C25 -> 0.25584376 | P25: =+G25/$C25 -> 3.673471 | Q25: =+H25/$C25 -> 19.608153 | R25: =+I25/$C25 -> 7.1995515 | S25: =+J25/$C25 -> 10.670714 | T25: =+K25/$C25 -> 3.9043478 | U25: =+L25/$C25 -> 0.23055639
B26: อ.นิคมพัฒนา | C26: =SUMIFS(Data!$Y$2:$Y$2000,Data!$E$2:$E$2000,WeightCal!B26) -> 2.3601782e+08 | D26: =SUMIFS(Data!AA$2:AA$2000,Data!$E$2:$E$2000,WeightCal!$B26) -> 8282468.5 | E26: =SUMIFS(Data!AB$2:AB$2000,Data!$E$2:$E$2000,WeightCal!$B26) -> 68002257 | F26: =SUMIFS(Data!AC$2:AC$2000,Data!$E$2:$E$2000,WeightCal!$B26) -> 49558161 | G26: =SUMIFS(Data!AD$2:AD$2000,Data!$E$2:$E$2000,WeightCal!$B26) -> 2.1274225e+08 | H26: =SUMIFS(Data!AE$2:AE$2000,Data!$E$2:$E$2000,WeightCal!$B26) -> 3.9060228e+09 | I26: =SUMIFS(Data!AF$2:AF$2000,Data!$E$2:$E$2000,WeightCal!$B26) -> 5.9234791e+09 | J26: =SUMIFS(Data!AG$2:AG$2000,Data!$E$2:$E$2000,WeightCal!$B26) -> 4.9833073e+09 | K26: =SUMIFS(Data!AH$2:AH$2000,Data!$E$2:$E$2000,WeightCal!$B26) -> 4.3252567e+09 | L26: =SUMIFS(Data!AI$2:AI$2000,Data!$E$2:$E$2000,WeightCal!$B26) -> 5.4502326e+08 | M26: =+D26/$C26 -> 0.035092555 | N26: =+E26/$C26 -> 0.2881234 | O26: =+F26/$C26 -> 0.20997635 | P26: =+G26/$C26 -> 0.90138214 | Q26: =+H26/$C26 -> 16.549694 | R26: =+I26/$C26 -> 25.097592 | S26: =+J26/$C26 -> 21.114114 | T26: =+K26/$C26 -> 18.325975 | U26: =+L26/$C26 -> 2.3092462
B27: อ.บ้านค่าย | C27: =SUMIFS(Data!$Y$2:$Y$2000,Data!$E$2:$E$2000,WeightCal!B27) -> 4.7492852e+08 | D27: =SUMIFS(Data!AA$2:AA$2000,Data!$E$2:$E$2000,WeightCal!$B27) -> 3.4010103e+09 | E27: =SUMIFS(Data!AB$2:AB$2000,Data!$E$2:$E$2000,WeightCal!$B27) -> 2.2354316e+09 | F27: =SUMIFS(Data!AC$2:AC$2000,Data!$E$2:$E$2000,WeightCal!$B27) -> 1.3363525e+09 | G27: =SUMIFS(Data!AD$2:AD$2000,Data!$E$2:$E$2000,WeightCal!$B27) -> 2.1178654e+09 | H27: =SUMIFS(Data!AE$2:AE$2000,Data!$E$2:$E$2000,WeightCal!$B27) -> 3.7830132e+09 | I27: =SUMIFS(Data!AF$2:AF$2000,Data!$E$2:$E$2000,WeightCal!$B27) -> 9.2197242e+09 | J27: =SUMIFS(Data!AG$2:AG$2000,Data!$E$2:$E$2000,WeightCal!$B27) -> 5.7637127e+09 | K27: =SUMIFS(Data!AH$2:AH$2000,Data!$E$2:$E$2000,WeightCal!$B27) -> 1.0444805e+10 | L27: =SUMIFS(Data!AI$2:AI$2000,Data!$E$2:$E$2000,WeightCal!$B27) -> 1.3230434e+09 | M27: =+D27/$C27 -> 7.1610993 | N27: =+E27/$C27 -> 4.7068802 | O27: =+F27/$C27 -> 2.8137971 | P27: =+G27/$C27 -> 4.459335 | Q27: =+H27/$C27 -> 7.9654371 | R27: =+I27/$C27 -> 19.412867 | S27: =+J27/$C27 -> 12.135958 | T27: =+K27/$C27 -> 21.992373 | U27: =+L27/$C27 -> 2.7857737
B28: อ.บ้านฉาง | C28: =SUMIFS(Data!$Y$2:$Y$2000,Data!$E$2:$E$2000,WeightCal!B28) -> 1.6325243e+08 | D28: =SUMIFS(Data!AA$2:AA$2000,Data!$E$2:$E$2000,WeightCal!$B28) -> 28225583 | E28: =SUMIFS(Data!AB$2:AB$2000,Data!$E$2:$E$2000,WeightCal!$B28) -> 5.9337894e+08 | F28: =SUMIFS(Data!AC$2:AC$2000,Data!$E$2:$E$2000,WeightCal!$B28) -> 19103918 | G28: =SUMIFS(Data!AD$2:AD$2000,Data!$E$2:$E$2000,WeightCal!$B28) -> 2.3101186e+08 | H28: =SUMIFS(Data!AE$2:AE$2000,Data!$E$2:$E$2000,WeightCal!$B28) -> 1.1588033e+09 | I28: =SUMIFS(Data!AF$2:AF$2000,Data!$E$2:$E$2000,WeightCal!$B28) -> 4.9622456e+09 | J28: =SUMIFS(Data!AG$2:AG$2000,Data!$E$2:$E$2000,WeightCal!$B28) -> 1.5235269e+09 | K28: =SUMIFS(Data!AH$2:AH$2000,Data!$E$2:$E$2000,WeightCal!$B28) -> 2.8936964e+09 | L28: =SUMIFS(Data!AI$2:AI$2000,Data!$E$2:$E$2000,WeightCal!$B28) -> 8.1374078e+08 | M28: =+D28/$C28 -> 0.17289533 | N28: =+E28/$C28 -> 3.6347327 | O28: =+F28/$C28 -> 0.11702073 | P28: =+G28/$C28 -> 1.4150592 | Q28: =+H28/$C28 -> 7.0982301 | R28: =+I28/$C28 -> 30.396151 | S28: =+J28/$C28 -> 9.3323381 | T28: =+K28/$C28 -> 17.725288 | U28: =+L28/$C28 -> 4.9845554
B29: อ.ปลวกแดง | C29: =SUMIFS(Data!$Y$2:$Y$2000,Data!$E$2:$E$2000,WeightCal!B29) -> 5.3099899e+08 | D29: =SUMIFS(Data!AA$2:AA$2000,Data!$E$2:$E$2000,WeightCal!$B29) -> 2.0885709e+09 | E29: =SUMIFS(Data!AB$2:AB$2000,Data!$E$2:$E$2000,WeightCal!$B29) -> 7.3140353e+08 | F29: =SUMIFS(Data!AC$2:AC$2000,Data!$E$2:$E$2000,WeightCal!$B29) -> 1.8995647e+08 | G29: =SUMIFS(Data!AD$2:AD$2000,Data!$E$2:$E$2000,WeightCal!$B29) -> 4.5635955e+08 | H29: =SUMIFS(Data!AE$2:AE$2000,Data!$E$2:$E$2000,WeightCal!$B29) -> 4.3795886e+09 | I29: =SUMIFS(Data!AF$2:AF$2000,Data!$E$2:$E$2000,WeightCal!$B29) -> 2.5488211e+10 | J29: =SUMIFS(Data!AG$2:AG$2000,Data!$E$2:$E$2000,WeightCal!$B29) -> 6.0215911e+09 | K29: =SUMIFS(Data!AH$2:AH$2000,Data!$E$2:$E$2000,WeightCal!$B29) -> 6.3197658e+09 | L29: =SUMIFS(Data!AI$2:AI$2000,Data!$E$2:$E$2000,WeightCal!$B29) -> 3.9501126e+08 | M29: =+D29/$C29 -> 3.933286 | N29: =+E29/$C29 -> 1.3774104 | O29: =+F29/$C29 -> 0.35773414 | P29: =+G29/$C29 -> 0.8594358 | Q29: =+H29/$C29 -> 8.2478284 | R29: =+I29/$C29 -> 48.000489 | S29: =+J29/$C29 -> 11.340118 | T29: =+K29/$C29 -> 11.901653 | U29: =+L29/$C29 -> 0.7439021
B30: อ.เมืองระยอง | C30: =SUMIFS(Data!$Y$2:$Y$2000,Data!$E$2:$E$2000,WeightCal!B30) -> 6.7402919e+08 | D30: =SUMIFS(Data!AA$2:AA$2000,Data!$E$2:$E$2000,WeightCal!$B30) -> 2.748406e+08 | E30: =SUMIFS(Data!AB$2:AB$2000,Data!$E$2:$E$2000,WeightCal!$B30) -> 9.0854386e+08 | F30: =SUMIFS(Data!AC$2:AC$2000,Data!$E$2:$E$2000,WeightCal!$B30) -> 2.9901234e+08 | G30: =SUMIFS(Data!AD$2:AD$2000,Data!$E$2:$E$2000,WeightCal!$B30) -> 3.0362703e+09 | H30: =SUMIFS(Data!AE$2:AE$2000,Data!$E$2:$E$2000,WeightCal!$B30) -> 1.4972565e+10 | I30: =SUMIFS(Data!AF$2:AF$2000,Data!$E$2:$E$2000,WeightCal!$B30) -> 9.5353291e+09 | J30: =SUMIFS(Data!AG$2:AG$2000,Data!$E$2:$E$2000,WeightCal!$B30) -> 9.2213699e+09 | K30: =SUMIFS(Data!AH$2:AH$2000,Data!$E$2:$E$2000,WeightCal!$B30) -> 2.367874e+10 | L30: =SUMIFS(Data!AI$2:AI$2000,Data!$E$2:$E$2000,WeightCal!$B30) -> 9.5772295e+09 | M30: =+D30/$C30 -> 0.40775771 | N30: =+E30/$C30 -> 1.3479295 | O30: =+F30/$C30 -> 0.44361927 | P30: =+G30/$C30 -> 4.504657 | Q30: =+H30/$C30 -> 22.213526 | R30: =+I30/$C30 -> 14.14676 | S30: =+J30/$C30 -> 13.680965 | T30: =+K30/$C30 -> 35.13014 | U30: =+L30/$C30 -> 14.208924
B31: อ.วังจันทร์ | C31: =SUMIFS(Data!$Y$2:$Y$2000,Data!$E$2:$E$2000,WeightCal!B31) -> 3.7327439e+08 | D31: =SUMIFS(Data!AA$2:AA$2000,Data!$E$2:$E$2000,WeightCal!$B31) -> 2.2055851e+09 | E31: =SUMIFS(Data!AB$2:AB$2000,Data!$E$2:$E$2000,WeightCal!$B31) -> 60199019 | F31: =SUMIFS(Data!AC$2:AC$2000,Data!$E$2:$E$2000,WeightCal!$B31) -> 5.9119277e+08 | G31: =SUMIFS(Data!AD$2:AD$2000,Data!$E$2:$E$2000,WeightCal!$B31) -> 1.9507887e+09 | H31: =SUMIFS(Data!AE$2:AE$2000,Data!$E$2:$E$2000,WeightCal!$B31) -> 4.0399883e+09 | I31: =SUMIFS(Data!AF$2:AF$2000,Data!$E$2:$E$2000,WeightCal!$B31) -> 2.3301737e+09 | J31: =SUMIFS(Data!AG$2:AG$2000,Data!$E$2:$E$2000,WeightCal!$B31) -> 6.5628764e+09 | K31: =SUMIFS(Data!AH$2:AH$2000,Data!$E$2:$E$2000,WeightCal!$B31) -> 1.8601813e+09 | L31: =SUMIFS(Data!AI$2:AI$2000,Data!$E$2:$E$2000,WeightCal!$B31) -> 1.4507909e+08 | M31: =+D31/$C31 -> 5.9087501 | N31: =+E31/$C31 -> 0.16127284 | O31: =+F31/$C31 -> 1.5838021 | P31: =+G31/$C31 -> 5.2261521 | Q31: =+H31/$C31 -> 10.823106 | R31: =+I31/$C31 -> 6.2425223 | S31: =+J31/$C31 -> 17.581909 | T31: =+K31/$C31 -> 4.9834152 | U31: =+L31/$C31 -> 0.38866607
A32: จ.จันทบุรี | B32: อ.แก่งหางแมว | C32: =SUMIFS(Data!$Y$2:$Y$2000,Data!$E$2:$E$2000,WeightCal!B32) -> 1.2170897e+09 | D32: =SUMIFS(Data!AA$2:AA$2000,Data!$E$2:$E$2000,WeightCal!$B32) -> 2.4472078e+10 | E32: =SUMIFS(Data!AB$2:AB$2000,Data!$E$2:$E$2000,WeightCal!$B32) -> 3.3138118e+08 | F32: =SUMIFS(Data!AC$2:AC$2000,Data!$E$2:$E$2000,WeightCal!$B32) -> 9.8243835e+08 | G32: =SUMIFS(Data!AD$2:AD$2000,Data!$E$2:$E$2000,WeightCal!$B32) -> 3.2003874e+09 | H32: =SUMIFS(Data!AE$2:AE$2000,Data!$E$2:$E$2000,WeightCal!$B32) -> 3.1194464e+10 | I32: =SUMIFS(Data!AF$2:AF$2000,Data!$E$2:$E$2000,WeightCal!$B32) -> 1.6906497e+10 | J32: =SUMIFS(Data!AG$2:AG$2000,Data!$E$2:$E$2000,WeightCal!$B32) -> 1.4555759e+10 | K32: =SUMIFS(Data!AH$2:AH$2000,Data!$E$2:$E$2000,WeightCal!$B32) -> 2.8899234e+09 | L32: =SUMIFS(Data!AI$2:AI$2000,Data!$E$2:$E$2000,WeightCal!$B32) -> 7.2120174e+08 | M32: =+D32/$C32 -> 20.107045 | N32: =+E32/$C32 -> 0.27227341 | O32: =+F32/$C32 -> 0.80720288 | P32: =+G32/$C32 -> 2.629541 | Q32: =+H32/$C32 -> 25.630373 | R32: =+I32/$C32 -> 13.89092 | S32: =+J32/$C32 -> 11.959479 | T32: =+K32/$C32 -> 2.3744538 | U32: =+L32/$C32 -> 0.5925625
B33: อ.ขลุง | C33: =SUMIFS(Data!$Y$2:$Y$2000,Data!$E$2:$E$2000,WeightCal!B33) -> 7.8444901e+08 | D33: =SUMIFS(Data!AA$2:AA$2000,Data!$E$2:$E$2000,WeightCal!$B33) -> 5.7597714e+09 | E33: =SUMIFS(Data!AB$2:AB$2000,Data!$E$2:$E$2000,WeightCal!$B33) -> 1.0124783e+08 | F33: =SUMIFS(Data!AC$2:AC$2000,Data!$E$2:$E$2000,WeightCal!$B33) -> 8.1944157e+08 | G33: =SUMIFS(Data!AD$2:AD$2000,Data!$E$2:$E$2000,WeightCal!$B33) -> 1.55171e+09 | H33: =SUMIFS(Data!AE$2:AE$2000,Data!$E$2:$E$2000,WeightCal!$B33) -> 3.7705295e+09 | I33: =SUMIFS(Data!AF$2:AF$2000,Data!$E$2:$E$2000,WeightCal!$B33) -> 5.00712e+09 | J33: =SUMIFS(Data!AG$2:AG$2000,Data!$E$2:$E$2000,WeightCal!$B33) -> 8.1876937e+09 | K33: =SUMIFS(Data!AH$2:AH$2000,Data!$E$2:$E$2000,WeightCal!$B33) -> 4.353716e+09 | L33: =SUMIFS(Data!AI$2:AI$2000,Data!$E$2:$E$2000,WeightCal!$B33) -> 1.3055062e+10 | M33: =+D33/$C33 -> 7.3424421 | N33: =+E33/$C33 -> 0.12906872 | O33: =+F33/$C33 -> 1.0446078 | P33: =+G33/$C33 -> 1.978089 | Q33: =+H33/$C33 -> 4.806596 | R33: =+I33/$C33 -> 6.382977 | S33: =+J33/$C33 -> 10.437509 | T33: =+K33/$C33 -> 5.5500306 | U33: =+L33/$C33 -> 16.642334
B34: อ.เขาคิชฌกูฏ | C34: =SUMIFS(Data!$Y$2:$Y$2000,Data!$E$2:$E$2000,WeightCal!B34) -> 7.8058342e+08 | D34: =SUMIFS(Data!AA$2:AA$2000,Data!$E$2:$E$2000,WeightCal!$B34) -> 2.1036549e+10 | E34: =SUMIFS(Data!AB$2:AB$2000,Data!$E$2:$E$2000,WeightCal!$B34) -> 3.0791952e+08 | F34: =SUMIFS(Data!AC$2:AC$2000,Data!$E$2:$E$2000,WeightCal!$B34) -> 2.6974532e+08 | G34: =SUMIFS(Data!AD$2:AD$2000,Data!$E$2:$E$2000,WeightCal!$B34) -> 3.2929704e+09 | H34: =SUMIFS(Data!AE$2:AE$2000,Data!$E$2:$E$2000,WeightCal!$B34) -> 9.743088e+09 | I34: =SUMIFS(Data!AF$2:AF$2000,Data!$E$2:$E$2000,WeightCal!$B34) -> 1.998408e+10 | J34: =SUMIFS(Data!AG$2:AG$2000,Data!$E$2:$E$2000,WeightCal!$B34) -> 1.1993061e+10 | K34: =SUMIFS(Data!AH$2:AH$2000,Data!$E$2:$E$2000,WeightCal!$B34) -> 2.766966e+09 | L34: =SUMIFS(Data!AI$2:AI$2000,Data!$E$2:$E$2000,WeightCal!$B34) -> 1.7355132e+09 | M34: =+D34/$C34 -> 26.949777 | N34: =+E34/$C34 -> 0.39447356 | O34: =+F34/$C34 -> 0.34556886 | P34: =+G34/$C34 -> 4.2186016 | Q34: =+H34/$C34 -> 12.481803 | R34: =+I34/$C34 -> 25.601466 | S34: =+J34/$C34 -> 15.364227 | T34: =+K34/$C34 -> 3.544741 | U34: =+L34/$C34 -> 2.2233539
B35: อ.ท่าใหม่ | C35: =SUMIFS(Data!$Y$2:$Y$2000,Data!$E$2:$E$2000,WeightCal!B35) -> 6.2608534e+08 | D35: =SUMIFS(Data!AA$2:AA$2000,Data!$E$2:$E$2000,WeightCal!$B35) -> 3.4402338e+09 | E35: =SUMIFS(Data!AB$2:AB$2000,Data!$E$2:$E$2000,WeightCal!$B35) -> 1.2745473e+08 | F35: =SUMIFS(Data!AC$2:AC$2000,Data!$E$2:$E$2000,WeightCal!$B35) -> 2.0261919e+08 | G35: =SUMIFS(Data!AD$2:AD$2000,Data!$E$2:$E$2000,WeightCal!$B35) -> 2.4304624e+09 | H35: =SUMIFS(Data!AE$2:AE$2000,Data!$E$2:$E$2000,WeightCal!$B35) -> 2.6015466e+09 | I35: =SUMIFS(Data!AF$2:AF$2000,Data!$E$2:$E$2000,WeightCal!$B35) -> 4.7944848e+09 | J35: =SUMIFS(Data!AG$2:AG$2000,Data!$E$2:$E$2000,WeightCal!$B35) -> 1.5012603e+10 | K35: =SUMIFS(Data!AH$2:AH$2000,Data!$E$2:$E$2000,WeightCal!$B35) -> 6.1521985e+09 | L35: =SUMIFS(Data!AI$2:AI$2000,Data!$E$2:$E$2000,WeightCal!$B35) -> 3.6518247e+09 | M35: =+D35/$C35 -> 5.4948321 | N35: =+E35/$C35 -> 0.20357405 | O35: =+F35/$C35 -> 0.32362871 | P35: =+G35/$C35 -> 3.8819986 | Q35: =+H35/$C35 -> 4.1552589 | R35: =+I35/$C35 -> 7.6578775 | S35: =+J35/$C35 -> 23.978525 | T35: =+K35/$C35 -> 9.8264536 | U35: =+L35/$C35 -> 5.8327907
B36: อ.นายายอาม | C36: =SUMIFS(Data!$Y$2:$Y$2000,Data!$E$2:$E$2000,WeightCal!B36) -> 2.8611401e+08 | D36: =SUMIFS(Data!AA$2:AA$2000,Data!$E$2:$E$2000,WeightCal!$B36) -> 7.7594037e+08 | E36: =SUMIFS(Data!AB$2:AB$2000,Data!$E$2:$E$2000,WeightCal!$B36) -> 44705813 | F36: =SUMIFS(Data!AC$2:AC$2000,Data!$E$2:$E$2000,WeightCal!$B36) -> 7.6787215e+08 | G36: =SUMIFS(Data!AD$2:AD$2000,Data!$E$2:$E$2000,WeightCal!$B36) -> 6.6430993e+08 | H36: =SUMIFS(Data!AE$2:AE$2000,Data!$E$2:$E$2000,WeightCal!$B36) -> 7.603924e+08 | I36: =SUMIFS(Data!AF$2:AF$2000,Data!$E$2:$E$2000,WeightCal!$B36) -> 1.9696791e+09 | J36: =SUMIFS(Data!AG$2:AG$2000,Data!$E$2:$E$2000,WeightCal!$B36) -> 9.2486442e+09 | K36: =SUMIFS(Data!AH$2:AH$2000,Data!$E$2:$E$2000,WeightCal!$B36) -> 1.3940387e+09 | L36: =SUMIFS(Data!AI$2:AI$2000,Data!$E$2:$E$2000,WeightCal!$B36) -> 1.9773658e+09 | M36: =+D36/$C36 -> 2.7119971 | N36: =+E36/$C36 -> 0.15625174 | O36: =+F36/$C36 -> 2.6837978 | P36: =+G36/$C36 -> 2.3218364 | Q36: =+H36/$C36 -> 2.6576552 | R36: =+I36/$C36 -> 6.8842455 | S36: =+J36/$C36 -> 32.325031 | T36: =+K36/$C36 -> 4.8723189 | U36: =+L36/$C36 -> 6.9111112
